Workbook
Name ACTION: #REF!
Name ACTION: #REF!

Sheet Cover
B2: TEST REPORT DOCUMENT
A4: Project Name | B4: Arden | E4: Creator | F4: Arden project team
A5: Project Code | B5: ARDEN | E5: Issue Date | F5: 31 October 2026
A6: Document Code | B6: =B5&"_TestReport_v1.2" -> ARDEN_TestReport_v1.2 | E6: Version | F6: 1.2
A9: Record of change
A10: Effective Date | B10: Version | C10: Change Item | D10: *A,D,M | E10: Change description | F10: Reference
A11: 31 October 2026 | B11: 1.2 | C11: Expanded automated checkout | D11: M | E11: Local run of 387 tests on 31 October 2026 by Quốc Anh: 380 passed, 7 skipped, 0 failed. | F11: feat/workspace-shell-polish @ 045a7b5; pnpm test, pnpm test:remote, and the release and pull-request node tests.

Sheet Test Cases
D1: TEST CASE LIST
B3: Project Name | D3: =Cover!B4 -> Arden
B4: Project Code | D4: =Cover!B5 -> ARDEN
B5: Test Environment Setup Description | D5: Checked source definitions on feat/workspace-shell-polish at commit 045a7b5b07c4746f32d447eb707c026d875016ef. All 387 Node/Vitest checks are individually listed in nine feature sheets. Reported: 380 passed; 7 API live-integration tests skipped for unconfigured Supabase or arden_test_* PostgreSQL; 0 failed. Fifty separate manually designed scenarios remain Pending and are not counted in automated totals.
B8: No | C8: Function Name | D8: Sheet Name | E8: Description | F8: Pre-Condition
B9: 1 | C9: UI Account & Org | D9: Feature1 | E9: Account, Invitations and Organization Management (70 source-defined automated tests). | F9: UI view-model and component tests covering login, membership, invitations, organization governance and copy.
B10: 2 | C10: UI Knowledge/Notes | D10: Feature2 | E10: Private Notes, Knowledge Library and Reader Experience (63 source-defined automated tests). | F10: UI tests for documents, drafts, review surfaces, knowledge states, PDF and citation presentation.
B11: 3 | C11: UI Workspace | D11: Feature3 | E11: Workspace Navigation and Shared UI Behaviors (35 source-defined automated tests). | F11: Workspace shell, application API client, cancellation, navigation and shared UI-contract checks.
B12: 4 | C12: API Auth & App | D12: Feature4 | E12: API App, Authentication and Email (74 source-defined automated tests). | F12: API application requests, authentication, local/dev identity constraints and SMTP behavior.
B13: 5 | C13: API Knowledge | D13: Feature5 | E13: API Knowledge Governance and Answers (36 source-defined automated tests). | F13: Knowledge policy, review decisions/queues, evidence contracts and source citations.
B14: 6 | C14: API Data & Index | D14: Feature6 | E14: API Repository, Migrations, Private Storage and Indexing (33 source-defined automated tests). | F14: Database authorization, migrations, content storage, indexing worker and contract tests.
B15: 7 | C15: Desktop & Domain | D15: Feature7 | E15: Desktop Request Protection and Domain Semantics (12 source-defined automated tests). | F15: Electron request policy checks and shared domain semantic-document validation.
B16: 8 | C16: Remote Workflow | D16: Feature8 | E16: Remote Workflow and Exclusive-Lease Protection (16 source-defined automated tests). | F16: Remote session orchestration, safe failure handling and frontend/backend startup sequence.
B17: 9 | C17: Release & PR | D17: Feature9 | E17: Release Pipeline, Migration, Transport and PR Guardrails (48 source-defined automated tests). | F17: Release and pull-request tooling, version identity, migrations and bounded deployment transport.
B18: 10 | C18: Manual Test Design | D18: Manual Plan | E18: 50 supplemental manual scenarios; planned, not part of the 387 executed/skip test inventory. | F18: Execution receipt not provided; all cases remain Pending.

Sheet Test Statistics
B1: TEST STATISTICS
B3: Project Name | C3: =Cover!B4 -> Arden | E3: Creator | G3: Arden project team
B4: Project Code | C4: =Cover!B5 -> ARDEN | E4: Reviewer/Approver | G4: Source SHA pinned
B5: Document Code | C5: =Cover!B6 -> ARDEN_TestReport_v1.2 | E5: Issue Date | H5: 31 October 2026
B6: Notes | C6: Local run on 31 October 2026, tester Quốc Anh, on feat/workspace-shell-polish at 045a7b5. Commands: pnpm test, pnpm test:remote, and the release and pull-request node tests. Result: 387 tests, 380 passed, 7 skipped, 0 failed. The seven skips are one live Supabase auth check and six PostgreSQL row-level-security checks; those environments were not configured. Areas: UI 168 passed; API 136 passed and 7 skipped; Desktop 7; Domain 5; Remote workflow 16; Release and pull-request checks 48. The 50 manual scenarios are pending and are not in this total.
B10: No | C10: Module code | D10: Passed | E10: Failed | F10: Pending | G10: Skipped | H10: Number of test cases
B11: 1 | C11: ='Feature 1'!B2 -> UI Account & Org | D11: ='Feature 1'!B6 -> 70 | E11: ='Feature 1'!C6 -> 0 | F11: ='Feature 1'!D6 -> 0 | G11: ='Feature 1'!E6 -> 0 | H11: ='Feature 1'!B4 -> 70
B12: 2 | C12: ='Feature 2'!B2 -> UI Knowledge/Notes | D12: ='Feature 2'!B6 -> 63 | E12: ='Feature 2'!C6 -> 0 | F12: ='Feature 2'!D6 -> 0 | G12: ='Feature 2'!E6 -> 0 | H12: ='Feature 2'!B4 -> 63
B13: 3 | C13: ='Feature 3'!B2 -> UI Workspace | D13: ='Feature 3'!B6 -> 35 | E13: ='Feature 3'!C6 -> 0 | F13: ='Feature 3'!D6 -> 0 | G13: ='Feature 3'!E6 -> 0 | H13: ='Feature 3'!B4 -> 35
B14: 4 | C14: ='Feature 4'!B2 -> API Auth & App | D14: ='Feature 4'!B6 -> 73 | E14: ='Feature 4'!C6 -> 0 | F14: ='Feature 4'!D6 -> 0 | G14: ='Feature 4'!E6 -> 1 | H14: ='Feature 4'!B4 -> 74
B15: 5 | C15: ='Feature 5'!B2 -> API Knowledge | D15: ='Feature 5'!B6 -> 36 | E15: ='Feature 5'!C6 -> 0 | F15: ='Feature 5'!D6 -> 0 | G15: ='Feature 5'!E6 -> 0 | H15: ='Feature 5'!B4 -> 36
B16: 6 | C16: ='Feature 6'!B2 -> API Data & Index | D16: ='Feature 6'!B6 -> 27 | E16: ='Feature 6'!C6 -> 0 | F16: ='Feature 6'!D6 -> 0 | G16: ='Feature 6'!E6 -> 6 | H16: ='Feature 6'!B4 -> 33
B17: 7 | C17: ='Feature 7'!B2 -> Desktop & Domain | D17: ='Feature 7'!B6 -> 12 | E17: ='Feature 7'!C6 -> 0 | F17: ='Feature 7'!D6 -> 0 | G17: ='Feature 7'!E6 -> 0 | H17: ='Feature 7'!B4 -> 12
B18: 8 | C18: ='Feature 8'!B2 -> Remote Workflow | D18: ='Feature 8'!B6 -> 16 | E18: ='Feature 8'!C6 -> 0 | F18: ='Feature 8'!D6 -> 0 | G18: ='Feature 8'!E6 -> 0 | H18: ='Feature 8'!B4 -> 16
B19: 9 | C19: ='Feature 9'!B2 -> Release & PR | D19: ='Feature 9'!B6 -> 48 | E19: ='Feature 9'!C6 -> 0 | F19: ='Feature 9'!D6 -> 0 | G19: ='Feature 9'!E6 -> 0 | H19: ='Feature 9'!B4 -> 48
C21: Sub total | D21: =SUM(D11:D19) -> 380 | E21: =SUM(E11:E19) -> 0 | F21: =SUM(F11:F19) -> 0 | G21: =SUM(G11:G19) -> 7 | H21: =SUM(H11:H19) -> 387
C23: Test coverage | E23: =IFERROR((D21+E21)*100/(H21-G21),0) -> 100 | F23: %
C24: Test successful coverage | E24: =IFERROR(D21*100/(H21-G21),0) -> 100 | F24: %

Sheet Feature 1
A2: Feature | B2: UI Account & Org | R2: Passed
A3: Test requirement | B3: UI view-model and component tests covering login, membership, invitations, organization governance and copy. | R3: Failed
A4: Number of TCs | B4: =COUNTA($F$12:$F$998) -> 70 | R4: Pending
A5: Testing Round | B5: Passed | C5: Failed | D5: Pending | E5: Skipped | R5: Skipped
A6: Round 1 | B6: =COUNTIF($F$12:$F$998,B$5) -> 70 | C6: =COUNTIF($F$12:$F$998,C$5) -> 0 | D6: =COUNTIF($F$12:$F$998,D$5) -> 0 | E6: =COUNTIF($F$12:$F$998,E$5) -> 0
A7: Round 2 | B7: =COUNTIF($I$12:$I$998,B$5) -> 0 | C7: =COUNTIF($I$12:$I$998,C$5) -> 0 | D7: =COUNTIF($I$12:$I$998,D$5) -> 0 | E7: =COUNTIF($I$12:$I$998,E$5) -> 0
A8: Round 3 | B8: =COUNTIF($L$12:$L$998,B$5) -> 0 | C8: =COUNTIF($L$12:$L$998,C$5) -> 0 | D8: =COUNTIF($L$12:$L$998,D$5) -> 0 | E8: =COUNTIF($L$12:$L$998,E$5) -> 0
A10: Test Case ID | B10: Test Case Description | C10: Test Case Procedure | D10: Expected Results | E10: Pre-conditions | F10: Round 1 | G10: Test date | H10: Tester | I10: Round 2 | J10: Test date | K10: Tester | L10: Round 3 | M10: Test date | N10: Tester | O10: Note
A11: adminDetailIslands (4)
A12: AT-001 | B12: shows the end date for a grant that expires | C12: 1. Load the source-defined test fixtures. 2. Run this check using the configured repository test runner. 3. Exercise: shows the end date for a grant that expires 4. Verify the test's assertions and side effects. | D12: shows the end date for a grant that expires. Expected UI text, state and presentation appear in the test assertions. | E12: Repository UI test fixtures; component/model mocks and test runner configured as in source. | F12: Passed | H12: Quốc Anh | O12: UI source: packages/ui/tests/adminDetailIslands.test.ts:7 Passed on 31 October 2026 in the local run of 387 tests (380 passed, 7 skipped, 0 failed) on feat/workspace-shell-polish at 045a7b5.
A13: AT-002 | B13: shows the start date for an open-ended grant | C13: 1. Load the source-defined test fixtures. 2. Run this check using the configured repository test runner. 3. Exercise: shows the start date for an open-ended grant 4. Verify the test's assertions and side effects. | D13: shows the start date for an open-ended grant. Expected UI text, state and presentation appear in the test assertions. | E13: Repository UI test fixtures; component/model mocks and test runner configured as in source. | F13: Passed | H13: Quốc Anh | O13: UI source: packages/ui/tests/adminDetailIslands.test.ts:11 Passed on 31 October 2026 in the local run of 387 tests (380 passed, 7 skipped, 0 failed) on feat/workspace-shell-polish at 045a7b5.
A14: AT-003 | B14: describes department and organization scopes | C14: 1. Load the source-defined test fixtures. 2. Run this check using the configured repository test runner. 3. Exercise: describes department and organization scopes 4. Verify the test's assertions and side effects. | D14: describes department and organization scopes. All declared source assertions and state checks satisfy the named behavior. | E14: Repository UI test fixtures; component/model mocks and test runner configured as in source. | F14: Passed | H14: Quốc Anh | O14: UI source: packages/ui/tests/adminDetailIslands.test.ts:17 Passed on 31 October 2026 in the local run of 387 tests (380 passed, 7 skipped, 0 failed) on feat/workspace-shell-polish at 045a7b5.
A15: AT-004 | B15: does not label an unassigned organization administrator as awaiting assignment | C15: 1. Load the source-defined test fixtures. 2. Run this check using the configured repository test runner. 3. Exercise: does not label an unassigned organization administrator as awaiting assignment 4. Verify the test's assertions and side effects. | D15: does not label an unassigned organization administrator as awaiting assignment. The named invariant holds under the exercised input. | E15: Repository UI test fixtures; component/model mocks and test runner configured as in source. | F15: Passed | H15: Quốc Anh | O15: UI source: packages/ui/tests/adminDetailIslands.test.ts:24 Passed on 31 October 2026 in the local run of 387 tests (380 passed, 7 skipped, 0 failed) on feat/workspace-shell-polish at 045a7b5.
A16: invitationFeedback (5)
A17: AT-005 | B17: returns an acceptance error for the shared signed-in and signed-out page area | C17: 1. Load the source-defined test fixtures. 2. Run this check using the configured repository test runner. 3. Exercise: returns an acceptance error for the shared signed-in and signed-out page area 4. Verify the test's assertions and side effects. | D17: returns an acceptance error for the shared signed-in and signed-out page area. The response or exposed contract matches the expected fixture and assertions. | E17: Repository UI test fixtures; component/model mocks and test runner configured as in source. | F17: Passed | H17: Quốc Anh | O17: UI source: packages/ui/tests/invitationFeedback.test.ts:50 Passed on 31 October 2026 in the local run of 387 tests (380 passed, 7 skipped, 0 failed) on feat/workspace-shell-polish at 045a7b5.
A18: AT-006 | B18: shows a success message when no error is present | C18: 1. Load the source-defined test fixtures. 2. Run this check using the configured repository test runner. 3. Exercise: shows a success message when no error is present 4. Verify the test's assertions and side effects. | D18: shows a success message when no error is present. Expected UI text, state and presentation appear in the test assertions. | E18: Repository UI test fixtures; component/model mocks and test runner configured as in source. | F18: Passed | H18: Quốc Anh | O18: UI source: packages/ui/tests/invitationFeedback.test.ts:56 Passed on 31 October 2026 in the local run of 387 tests (380 passed, 7 skipped, 0 failed) on feat/workspace-shell-polish at 045a7b5.
A19: AT-007 | B19: does not render empty feedback | C19: 1. Load the source-defined test fixtures. 2. Run this check using the configured repository test runner. 3. Exercise: does not render empty feedback 4. Verify the test's assertions and side effects. | D19: does not render empty feedback. The named invariant holds under the exercised input. | E19: Repository UI test fixtures; component/model mocks and test runner configured as in source. | F19: Passed | H19: Quốc Anh | O19: UI source: packages/ui/tests/invitationFeedback.test.ts:62 Passed on 31 October 2026 in the local run of 387 tests (380 passed, 7 skipped, 0 failed) on feat/workspace-shell-polish at 045a7b5.
A20: AT-008 | B20: keeps an acceptance error visible after sign-in and leaves the retry action available | C20: 1. Load the source-defined test fixtures. 2. Run this check using the configured repository test runner. 3. Exercise: keeps an acceptance error visible after sign-in and leaves the retry action available 4. Verify the test's assertions and side effects. | D20: keeps an acceptance error visible after sign-in and leaves the retry action available. The named invariant holds under the exercised input. | E20: Repository UI test fixtures; component/model mocks and test runner configured as in source. | F20: Passed | H20: Quốc Anh | O20: UI source: packages/ui/tests/invitationFeedback.test.ts:66 Passed on 31 October 2026 in the local run of 387 tests (380 passed, 7 skipped, 0 failed) on feat/workspace-shell-polish at 045a7b5.
A21: AT-009 | B21: does not call an invitation unavailable when its acceptance response is lost | C21: 1. Load the source-defined test fixtures. 2. Run this check using the configured repository test runner. 3. Exercise: does not call an invitation unavailable when its acceptance response is lost 4. Verify the test's assertions and side effects. | D21: does not call an invitation unavailable when its acceptance response is lost. The named invariant holds under the exercised input. | E21: Repository UI test fixtures; component/model mocks and test runner configured as in source. | F21: Passed | H21: Quốc Anh | O21: UI source: packages/ui/tests/invitationFeedback.test.ts:90 Passed on 31 October 2026 in the local run of 387 tests (380 passed, 7 skipped, 0 failed) on feat/workspace-shell-polish at 045a7b5.
A22: invitationStatus (3)
A23: AT-010 | B23: treats a pending invitation past expiry as expired | C23: 1. Load the source-defined test fixtures. 2. Run this check using the configured repository test runner. 3. Exercise: treats a pending invitation past expiry as expired 4. Verify the test's assertions and side effects. | D23: treats a pending invitation past expiry as expired. All declared source assertions and state checks satisfy the named behavior. | E23: Repository UI test fixtures; component/model mocks and test runner configured as in source. | F23: Passed | H23: Quốc Anh | O23: UI source: packages/ui/tests/invitationStatus.test.ts:8 Passed on 31 October 2026 in the local run of 387 tests (380 passed, 7 skipped, 0 failed) on feat/workspace-shell-polish at 045a7b5.
A24: AT-011 | B24: keeps server outcomes and maps unknown statuses to revoked | C24: 1. Load the source-defined test fixtures. 2. Run this check using the configured repository test runner. 3. Exercise: keeps server outcomes and maps unknown statuses to revoked 4. Verify the test's assertions and side effects. | D24: keeps server outcomes and maps unknown statuses to revoked. The named invariant holds under the exercised input. | E24: Repository UI test fixtures; component/model mocks and test runner configured as in source. | F24: Passed | H24: Quốc Anh | O24: UI source: packages/ui/tests/invitationStatus.test.ts:13 Passed on 31 October 2026 in the local run of 387 tests (380 passed, 7 skipped, 0 failed) on feat/workspace-shell-polish at 045a7b5.
A25: AT-012 | B25: counts every invitation once and orders actionable ones first | C25: 1. Load the source-defined test fixtures. 2. Run this check using the configured repository test runner. 3. Exercise: counts every invitation once and orders actionable ones first 4. Verify the test's assertions and side effects. | D25: counts every invitation once and orders actionable ones first. All declared source assertions and state checks satisfy the named behavior. | E25: Repository UI test fixtures; component/model mocks and test runner configured as in source. | F25: Passed | H25: Quốc Anh | O25: UI source: packages/ui/tests/invitationStatus.test.ts:19 Passed on 31 October 2026 in the local run of 387 tests (380 passed, 7 skipped, 0 failed) on feat/workspace-shell-polish at 045a7b5.
A26: memberAdministration (6)
A27: AT-013 | B27: keeps organization administrators available in the member manager | C27: 1. Load the source-defined test fixtures. 2. Run this check using the configured repository test runner. 3. Exercise: keeps organization administrators available in the member manager 4. Verify the test's assertions and side effects. | D27: keeps organization administrators available in the member manager. The named invariant holds under the exercised input. | E27: Repository UI test fixtures; component/model mocks and test runner configured as in source. | F27: Passed | H27: Quốc Anh | O27: UI source: packages/ui/tests/memberAdministration.test.ts:19 Passed on 31 October 2026 in the local run of 387 tests (380 passed, 7 skipped, 0 failed) on feat/workspace-shell-polish at 045a7b5.
A28: AT-014 | B28: includes organization administrators whose department membership is affected by deletion | C28: 1. Load the source-defined test fixtures. 2. Run this check using the configured repository test runner. 3. Exercise: includes organization administrators whose department membership is affected by deletion 4. Verify the test's assertions and side effects. | D28: includes organization administrators whose department membership is affected by deletion. All declared source assertions and state checks satisfy the named behavior. | E28: Repository UI test fixtures; component/model mocks and test runner configured as in source. | F28: Passed | H28: Quốc Anh | O28: UI source: packages/ui/tests/memberAdministration.test.ts:24 Passed on 31 October 2026 in the local run of 387 tests (380 passed, 7 skipped, 0 failed) on feat/workspace-shell-polish at 045a7b5.
A29: AT-015 | B29: does not classify an unassigned organization administrator as waiting for assignment | C29: 1. Load the source-defined test fixtures. 2. Run this check using the configured repository test runner. 3. Exercise: does not classify an unassigned organization administrator as waiting for assignment 4. Verify the test's assertions and side effects. | D29: does not classify an unassigned organization administrator as waiting for assignment. The named invariant holds under the exercised input. | E29: Repository UI test fixtures; component/model mocks and test runner configured as in source. | F29: Passed | H29: Quốc Anh | O29: UI source: packages/ui/tests/memberAdministration.test.ts:28 Passed on 31 October 2026 in the local run of 387 tests (380 passed, 7 skipped, 0 failed) on feat/workspace-shell-polish at 045a7b5.
A30: AT-016 | B30: shows active unassigned members only in the awaiting-assignment filter | C30: 1. Load the source-defined test fixtures. 2. Run this check using the configured repository test runner. 3. Exercise: shows active unassigned members only in the awaiting-assignment filter 4. Verify the test's assertions and side effects. | D30: shows active unassigned members only in the awaiting-assignment filter. Expected UI text, state and presentation appear in the test assertions. | E30: Repository UI test fixtures; component/model mocks and test runner configured as in source. | F30: Passed | H30: Quốc Anh | O30: UI source: packages/ui/tests/memberAdministration.test.ts:34 Passed on 31 October 2026 in the local run of 387 tests (380 passed, 7 skipped, 0 failed) on feat/workspace-shell-polish at 045a7b5.
A31: AT-017 | B31: does not treat a custom role named Department Administrator as an organization admin | C31: 1. Load the source-defined test fixtures. 2. Run this check using the configured repository test runner. 3. Exercise: does not treat a custom role named Department Administrator as an organization admin 4. Verify the test's assertions and side effects. | D31: does not treat a custom role named Department Administrator as an organization admin. The named invariant holds under the exercised input. | E31: Repository UI test fixtures; component/model mocks and test runner configured as in source. | F31: Passed | H31: Quốc Anh | O31: UI source: packages/ui/tests/memberAdministration.test.ts:42 Passed on 31 October 2026 in the local run of 387 tests (380 passed, 7 skipped, 0 failed) on feat/workspace-shell-polish at 045a7b5.
A32: AT-018 | B32: keeps the assignment and access consequences of department deletion | C32: 1. Load the source-defined test fixtures. 2. Run this check using the configured repository test runner. 3. Exercise: keeps the assignment and access consequences of department deletion 4. Verify the test's assertions and side effects. | D32: keeps the assignment and access consequences of department deletion. The named invariant holds under the exercised input. | E32: Repository UI test fixtures; component/model mocks and test runner configured as in source. | F32: Passed | H32: Quốc Anh | O32: UI source: packages/ui/tests/memberAdministration.test.ts:54 Passed on 31 October 2026 in the local run of 387 tests (380 passed, 7 skipped, 0 failed) on feat/workspace-shell-polish at 045a7b5.
A33: membershipAssignment (5)
A34: AT-019 | B34: keeps an active department-free member in the waiting room even with private workspace permission | C34: 1. Load the source-defined test fixtures. 2. Run this check using the configured repository test runner. 3. Exercise: keeps an active department-free member in the waiting room even with private workspace permission 4. Verify the test's assertions and side effects. | D34: keeps an active department-free member in the waiting room even with private workspace permission. The named invariant holds under the exercised input. | E34: Repository UI test fixtures; component/model mocks and test runner configured as in source. | F34: Passed | H34: Quốc Anh | O34: UI source: packages/ui/tests/membershipAssignment.test.ts:5 Passed on 31 October 2026 in the local run of 387 tests (380 passed, 7 skipped, 0 failed) on feat/workspace-shell-polish at 045a7b5.
A35: AT-020 | B35: keeps the organization administrator exception | C35: 1. Load the source-defined test fixtures. 2. Run this check using the configured repository test runner. 3. Exercise: keeps the organization administrator exception 4. Verify the test's assertions and side effects. | D35: keeps the organization administrator exception. The named invariant holds under the exercised input. | E35: Repository UI test fixtures; component/model mocks and test runner configured as in source. | F35: Passed | H35: Quốc Anh | O35: UI source: packages/ui/tests/membershipAssignment.test.ts:12 Passed on 31 October 2026 in the local run of 387 tests (380 passed, 7 skipped, 0 failed) on feat/workspace-shell-polish at 045a7b5.
A36: AT-021 | B36: does not send inactive memberships to the waiting room | C36: 1. Load the source-defined test fixtures. 2. Run this check using the configured repository test runner. 3. Exercise: does not send inactive memberships to the waiting room 4. Verify the test's assertions and side effects. | D36: does not send inactive memberships to the waiting room. The named invariant holds under the exercised input. | E36: Repository UI test fixtures; component/model mocks and test runner configured as in source. | F36: Passed | H36: Quốc Anh | O36: UI source: packages/ui/tests/membershipAssignment.test.ts:19 Passed on 31 October 2026 in the local run of 387 tests (380 passed, 7 skipped, 0 failed) on feat/workspace-shell-polish at 045a7b5.
A37: AT-022 | B37: does not claim private workspace access when the server denies it | C37: 1. Load the source-defined test fixtures. 2. Run this check using the configured repository test runner. 3. Exercise: does not claim private workspace access when the server denies it 4. Verify the test's assertions and side effects. | D37: does not claim private workspace access when the server denies it. The named invariant holds under the exercised input. | E37: Repository UI test fixtures; component/model mocks and test runner configured as in source. | F37: Passed | H37: Quốc Anh | O37: UI source: packages/ui/tests/membershipAssignment.test.ts:26 Passed on 31 October 2026 in the local run of 387 tests (380 passed, 7 skipped, 0 failed) on feat/workspace-shell-polish at 045a7b5.
A38: AT-023 | B38: uses a readable administrator label without exposing role codes | C38: 1. Load the source-defined test fixtures. 2. Run this check using the configured repository test runner. 3. Exercise: uses a readable administrator label without exposing role codes 4. Verify the test's assertions and side effects. | D38: uses a readable administrator label without exposing role codes. All declared source assertions and state checks satisfy the named behavior. | E38: Repository UI test fixtures; component/model mocks and test runner configured as in source. | F38: Passed | H38: Quốc Anh | O38: UI source: packages/ui/tests/membershipAssignment.test.ts:34 Passed on 31 October 2026 in the local run of 387 tests (380 passed, 7 skipped, 0 failed) on feat/workspace-shell-polish at 045a7b5.
A39: organizationWorkflow (32)
A40: AT-024 | B40: creates a normalized seven-day invitation without adding or mutating a member | C40: 1. Load the source-defined test fixtures. 2. Run this check using the configured repository test runner. 3. Exercise: creates a normalized seven-day invitation without adding or mutating a member 4. Verify the test's assertions and side effects. | D40: creates a normalized seven-day invitation without adding or mutating a member. All declared source assertions and state checks satisfy the named behavior. | E40: Repository UI test fixtures; component/model mocks and test runner configured as in source. | F40: Passed | H40: Quốc Anh | O40: UI source: packages/ui/tests/organizationWorkflow.test.ts:41 Passed on 31 October 2026 in the local run of 387 tests (380 passed, 7 skipped, 0 failed) on feat/workspace-shell-polish at 045a7b5.
A41: AT-025 | B41: accepts the matching account once and waits for department and role assignment | C41: 1. Load the source-defined test fixtures. 2. Run this check using the configured repository test runner. 3. Exercise: accepts the matching account once and waits for department and role assignment 4. Verify the test's assertions and side effects. | D41: accepts the matching account once and waits for department and role assignment. The authorized operation behaves as asserted by the test. | E41: Repository UI test fixtures; component/model mocks and test runner configured as in source. | F41: Passed | H41: Quốc Anh | O41: UI source: packages/ui/tests/organizationWorkflow.test.ts:62 Passed on 31 October 2026 in the local run of 387 tests (380 passed, 7 skipped, 0 failed) on feat/workspace-shell-polish at 045a7b5.
A42: AT-026 | B42: rejects duplicate invitation ID without changing the organization | C42: 1. Load the source-defined test fixtures. 2. Run this check using the configured repository test runner. 3. Exercise: rejects duplicate invitation ID without changing the organization 4. Verify the test's assertions and side effects. | D42: rejects duplicate invitation ID without changing the organization. Invalid or unauthorized behavior is blocked without a prohibited state change. | E42: Repository UI test fixtures; component/model mocks and test runner configured as in source. | F42: Passed | H42: Quốc Anh | O42: UI source: packages/ui/tests/organizationWorkflow.test.ts:84 Parameterized case: duplicate invitation ID Passed on 31 October 2026 in the local run of 387 tests (380 passed, 7 skipped, 0 failed) on feat/workspace-shell-polish at 045a7b5.
...

Sheet Feature 2
A2: Feature | B2: UI Knowledge/Notes | R2: Passed
A3: Test requirement | B3: UI tests for documents, drafts, review surfaces, knowledge states, PDF and citation presentation. | R3: Failed
A4: Number of TCs | B4: =COUNTA($F$12:$F$998) -> 63 | R4: Pending
A5: Testing Round | B5: Passed | C5: Failed | D5: Pending | E5: Skipped | R5: Skipped
A6: Round 1 | B6: =COUNTIF($F$12:$F$998,B$5) -> 63 | C6: =COUNTIF($F$12:$F$998,C$5) -> 0 | D6: =COUNTIF($F$12:$F$998,D$5) -> 0 | E6: =COUNTIF($F$12:$F$998,E$5) -> 0
A7: Round 2 | B7: =COUNTIF($I$12:$I$998,B$5) -> 0 | C7: =COUNTIF($I$12:$I$998,C$5) -> 0 | D7: =COUNTIF($I$12:$I$998,D$5) -> 0 | E7: =COUNTIF($I$12:$I$998,E$5) -> 0
A8: Round 3 | B8: =COUNTIF($L$12:$L$998,B$5) -> 0 | C8: =COUNTIF($L$12:$L$998,C$5) -> 0 | D8: =COUNTIF($L$12:$L$998,D$5) -> 0 | E8: =COUNTIF($L$12:$L$998,E$5) -> 0
A10: Test Case ID | B10: Test Case Description | C10: Test Case Procedure | D10: Expected Results | E10: Pre-conditions | F10: Round 1 | G10: Test date | H10: Tester | I10: Round 2 | J10: Test date | K10: Tester | L10: Round 3 | M10: Test date | N10: Tester | O10: Note
A11: ardenDocumentModel (5)
A12: AT-071 | B12: rejects unversioned stored text instead of keeping a second canonical format | C12: 1. Load the source-defined test fixtures. 2. Run this check using the configured repository test runner. 3. Exercise: rejects unversioned stored text instead of keeping a second canonical format 4. Verify the test's assertions and side effects. | D12: rejects unversioned stored text instead of keeping a second canonical format. Invalid or unauthorized behavior is blocked without a prohibited state change. | E12: Repository UI test fixtures; component/model mocks and test runner configured as in source. | F12: Passed | H12: Quốc Anh | O12: UI source: packages/ui/tests/ardenDocumentModel.test.ts:10 Passed on 31 October 2026 in the local run of 387 tests (380 passed, 7 skipped, 0 failed) on feat/workspace-shell-polish at 045a7b5.
A13: AT-072 | B13: round-trips supported blocks, stable ids, and inline formatting | C13: 1. Load the source-defined test fixtures. 2. Run this check using the configured repository test runner. 3. Exercise: round-trips supported blocks, stable ids, and inline formatting 4. Verify the test's assertions and side effects. | D13: round-trips supported blocks, stable ids, and inline formatting. All declared source assertions and state checks satisfy the named behavior. | E13: Repository UI test fixtures; component/model mocks and test runner configured as in source. | F13: Passed | H13: Quốc Anh | O13: UI source: packages/ui/tests/ardenDocumentModel.test.ts:17 Passed on 31 October 2026 in the local run of 387 tests (380 passed, 7 skipped, 0 failed) on feat/workspace-shell-polish at 045a7b5.
A14: AT-073 | B14: drops color and layout properties that are outside the fixed Arden format | C14: 1. Load the source-defined test fixtures. 2. Run this check using the configured repository test runner. 3. Exercise: drops color and layout properties that are outside the fixed Arden format 4. Verify the test's assertions and side effects. | D14: drops color and layout properties that are outside the fixed Arden format. All declared source assertions and state checks satisfy the named behavior. | E14: Repository UI test fixtures; component/model mocks and test runner configured as in source. | F14: Passed | H14: Quốc Anh | O14: UI source: packages/ui/tests/ardenDocumentModel.test.ts:38 Passed on 31 October 2026 in the local run of 387 tests (380 passed, 7 skipped, 0 failed) on feat/workspace-shell-polish at 045a7b5.
A15: AT-074 | B15: preserves styled text when an editor link has an unsupported scheme | C15: 1. Load the source-defined test fixtures. 2. Run this check using the configured repository test runner. 3. Exercise: preserves styled text when an editor link has an unsupported scheme 4. Verify the test's assertions and side effects. | D15: preserves styled text when an editor link has an unsupported scheme. The named invariant holds under the exercised input. | E15: Repository UI test fixtures; component/model mocks and test runner configured as in source. | F15: Passed | H15: Quốc Anh | O15: UI source: packages/ui/tests/ardenDocumentModel.test.ts:66 Passed on 31 October 2026 in the local run of 387 tests (380 passed, 7 skipped, 0 failed) on feat/workspace-shell-polish at 045a7b5.
A16: AT-075 | B16: rejects malformed or unsupported versioned content | C16: 1. Load the source-defined test fixtures. 2. Run this check using the configured repository test runner. 3. Exercise: rejects malformed or unsupported versioned content 4. Verify the test's assertions and side effects. | D16: rejects malformed or unsupported versioned content. Invalid or unauthorized behavior is blocked without a prohibited state change. | E16: Repository UI test fixtures; component/model mocks and test runner configured as in source. | F16: Passed | H16: Quốc Anh | O16: UI source: packages/ui/tests/ardenDocumentModel.test.ts:78 Passed on 31 October 2026 in the local run of 387 tests (380 passed, 7 skipped, 0 failed) on feat/workspace-shell-polish at 045a7b5.
A17: askArdenModel (2)
A18: AT-076 | B18: keeps real citations navigable | C18: 1. Load the source-defined test fixtures. 2. Run this check using the configured repository test runner. 3. Exercise: keeps real citations navigable 4. Verify the test's assertions and side effects. | D18: keeps real citations navigable. The named invariant holds under the exercised input. | E18: Repository UI test fixtures; component/model mocks and test runner configured as in source. | F18: Passed | H18: Quốc Anh | O18: UI source: packages/ui/tests/askArdenModel.test.ts:5 Passed on 31 October 2026 in the local run of 387 tests (380 passed, 7 skipped, 0 failed) on feat/workspace-shell-polish at 045a7b5.
A19: AT-077 | B19: marks an honest no-evidence response without inventing citations | C19: 1. Load the source-defined test fixtures. 2. Run this check using the configured repository test runner. 3. Exercise: marks an honest no-evidence response without inventing citations 4. Verify the test's assertions and side effects. | D19: marks an honest no-evidence response without inventing citations. All declared source assertions and state checks satisfy the named behavior. | E19: Repository UI test fixtures; component/model mocks and test runner configured as in source. | F19: Passed | H19: Quốc Anh | O19: UI source: packages/ui/tests/askArdenModel.test.ts:15 Passed on 31 October 2026 in the local run of 387 tests (380 passed, 7 skipped, 0 failed) on feat/workspace-shell-polish at 045a7b5.
A20: knowledgeAudience (3)
A21: AT-078 | B21: offers managed audiences only at their matching scope and groups at either scope | C21: 1. Load the source-defined test fixtures. 2. Run this check using the configured repository test runner. 3. Exercise: offers managed audiences only at their matching scope and groups at either scope 4. Verify the test's assertions and side effects. | D21: offers managed audiences only at their matching scope and groups at either scope. All declared source assertions and state checks satisfy the named behavior. | E21: Repository UI test fixtures; component/model mocks and test runner configured as in source. | F21: Passed | H21: Quốc Anh | O21: UI source: packages/ui/tests/knowledgeAudience.test.ts:11 Passed on 31 October 2026 in the local run of 387 tests (380 passed, 7 skipped, 0 failed) on feat/workspace-shell-polish at 045a7b5.
A22: AT-079 | B22: removes ALL_MEMBERS when switching from Organization to Department | C22: 1. Load the source-defined test fixtures. 2. Run this check using the configured repository test runner. 3. Exercise: removes ALL_MEMBERS when switching from Organization to Department 4. Verify the test's assertions and side effects. | D22: removes ALL_MEMBERS when switching from Organization to Department. All declared source assertions and state checks satisfy the named behavior. | E22: Repository UI test fixtures; component/model mocks and test runner configured as in source. | F22: Passed | H22: Quốc Anh | O22: UI source: packages/ui/tests/knowledgeAudience.test.ts:17 Passed on 31 October 2026 in the local run of 387 tests (380 passed, 7 skipped, 0 failed) on feat/workspace-shell-polish at 045a7b5.
A23: AT-080 | B23: rejects empty, duplicate, unknown and out-of-scope selections | C23: 1. Load the source-defined test fixtures. 2. Run this check using the configured repository test runner. 3. Exercise: rejects empty, duplicate, unknown and out-of-scope selections 4. Verify the test's assertions and side effects. | D23: rejects empty, duplicate, unknown and out-of-scope selections. Invalid or unauthorized behavior is blocked without a prohibited state change. | E23: Repository UI test fixtures; component/model mocks and test runner configured as in source. | F23: Passed | H23: Quốc Anh | O23: UI source: packages/ui/tests/knowledgeAudience.test.ts:21 Passed on 31 October 2026 in the local run of 387 tests (380 passed, 7 skipped, 0 failed) on feat/workspace-shell-polish at 045a7b5.
A24: knowledgeDocumentDetail (3)
A25: AT-081 | B25: marks a future publication as upcoming | C25: 1. Load the source-defined test fixtures. 2. Run this check using the configured repository test runner. 3. Exercise: marks a future publication as upcoming 4. Verify the test's assertions and side effects. | D25: marks a future publication as upcoming. All declared source assertions and state checks satisfy the named behavior. | E25: Repository UI test fixtures; component/model mocks and test runner configured as in source. | F25: Passed | H25: Quốc Anh | O25: UI source: packages/ui/tests/knowledgeDocumentDetail.test.ts:7 Passed on 31 October 2026 in the local run of 387 tests (380 passed, 7 skipped, 0 failed) on feat/workspace-shell-polish at 045a7b5.
A26: AT-082 | B26: marks a publication whose validity ended as expired | C26: 1. Load the source-defined test fixtures. 2. Run this check using the configured repository test runner. 3. Exercise: marks a publication whose validity ended as expired 4. Verify the test's assertions and side effects. | D26: marks a publication whose validity ended as expired. All declared source assertions and state checks satisfy the named behavior. | E26: Repository UI test fixtures; component/model mocks and test runner configured as in source. | F26: Passed | H26: Quốc Anh | O26: UI source: packages/ui/tests/knowledgeDocumentDetail.test.ts:11 Passed on 31 October 2026 in the local run of 387 tests (380 passed, 7 skipped, 0 failed) on feat/workspace-shell-polish at 045a7b5.
A27: AT-083 | B27: keeps an active publication effective | C27: 1. Load the source-defined test fixtures. 2. Run this check using the configured repository test runner. 3. Exercise: keeps an active publication effective 4. Verify the test's assertions and side effects. | D27: keeps an active publication effective. The named invariant holds under the exercised input. | E27: Repository UI test fixtures; component/model mocks and test runner configured as in source. | F27: Passed | H27: Quốc Anh | O27: UI source: packages/ui/tests/knowledgeDocumentDetail.test.ts:15 Passed on 31 October 2026 in the local run of 387 tests (380 passed, 7 skipped, 0 failed) on feat/workspace-shell-polish at 045a7b5.
A28: knowledgeLibrary (3)
A29: AT-084 | B29: matches governed metadata used by the search list | C29: 1. Load the source-defined test fixtures. 2. Run this check using the configured repository test runner. 3. Exercise: matches governed metadata used by the search list 4. Verify the test's assertions and side effects. | D29: matches governed metadata used by the search list. All declared source assertions and state checks satisfy the named behavior. | E29: Repository UI test fixtures; component/model mocks and test runner configured as in source. | F29: Passed | H29: Quốc Anh | O29: UI source: packages/ui/tests/knowledgeLibrary.test.ts:7 Passed on 31 October 2026 in the local run of 387 tests (380 passed, 7 skipped, 0 failed) on feat/workspace-shell-polish at 045a7b5.
A30: AT-085 | B30: does not match unrelated content | C30: 1. Load the source-defined test fixtures. 2. Run this check using the configured repository test runner. 3. Exercise: does not match unrelated content 4. Verify the test's assertions and side effects. | D30: does not match unrelated content. The named invariant holds under the exercised input. | E30: Repository UI test fixtures; component/model mocks and test runner configured as in source. | F30: Passed | H30: Quốc Anh | O30: UI source: packages/ui/tests/knowledgeLibrary.test.ts:14 Passed on 31 October 2026 in the local run of 387 tests (380 passed, 7 skipped, 0 failed) on feat/workspace-shell-polish at 045a7b5.
A31: AT-086 | B31: keeps private and in-review samples out of shared search | C31: 1. Load the source-defined test fixtures. 2. Run this check using the configured repository test runner. 3. Exercise: keeps private and in-review samples out of shared search 4. Verify the test's assertions and side effects. | D31: keeps private and in-review samples out of shared search. The named invariant holds under the exercised input. | E31: Repository UI test fixtures; component/model mocks and test runner configured as in source. | F31: Passed | H31: Quốc Anh | O31: UI source: packages/ui/tests/knowledgeLibrary.test.ts:18 Passed on 31 October 2026 in the local run of 387 tests (380 passed, 7 skipped, 0 failed) on feat/workspace-shell-polish at 045a7b5.
A32: knowledgePreviewModel (7)
A33: AT-087 | B33: blocks incomplete or private drafts from shared review | C33: 1. Load the source-defined test fixtures. 2. Run this check using the configured repository test runner. 3. Exercise: blocks incomplete or private drafts from shared review 4. Verify the test's assertions and side effects. | D33: blocks incomplete or private drafts from shared review. Invalid or unauthorized behavior is blocked without a prohibited state change. | E33: Repository UI test fixtures; component/model mocks and test runner configured as in source. | F33: Passed | H33: Quốc Anh | O33: UI source: packages/ui/tests/knowledgePreviewModel.test.ts:5 Passed on 31 October 2026 in the local run of 387 tests (380 passed, 7 skipped, 0 failed) on feat/workspace-shell-polish at 045a7b5.
A34: AT-088 | B34: keeps submitted content independent from later draft edits | C34: 1. Load the source-defined test fixtures. 2. Run this check using the configured repository test runner. 3. Exercise: keeps submitted content independent from later draft edits 4. Verify the test's assertions and side effects. | D34: keeps submitted content independent from later draft edits. The named invariant holds under the exercised input. | E34: Repository UI test fixtures; component/model mocks and test runner configured as in source. | F34: Passed | H34: Quốc Anh | O34: UI source: packages/ui/tests/knowledgePreviewModel.test.ts:15 Passed on 31 October 2026 in the local run of 387 tests (380 passed, 7 skipped, 0 failed) on feat/workspace-shell-polish at 045a7b5.
A35: AT-089 | B35: keeps approval non-active until explicit index-ready activation | C35: 1. Load the source-defined test fixtures. 2. Run this check using the configured repository test runner. 3. Exercise: keeps approval non-active until explicit index-ready activation 4. Verify the test's assertions and side effects. | D35: keeps approval non-active until explicit index-ready activation. The named invariant holds under the exercised input. | E35: Repository UI test fixtures; component/model mocks and test runner configured as in source. | F35: Passed | H35: Quốc Anh | O35: UI source: packages/ui/tests/knowledgePreviewModel.test.ts:25 Passed on 31 October 2026 in the local run of 387 tests (380 passed, 7 skipped, 0 failed) on feat/workspace-shell-polish at 045a7b5.
A36: AT-090 | B36: does not submit an unchanged published sample again | C36: 1. Load the source-defined test fixtures. 2. Run this check using the configured repository test runner. 3. Exercise: does not submit an unchanged published sample again 4. Verify the test's assertions and side effects. | D36: does not submit an unchanged published sample again. The named invariant holds under the exercised input. | E36: Repository UI test fixtures; component/model mocks and test runner configured as in source. | F36: Passed | H36: Quốc Anh | O36: UI source: packages/ui/tests/knowledgePreviewModel.test.ts:38 Passed on 31 October 2026 in the local run of 387 tests (380 passed, 7 skipped, 0 failed) on feat/workspace-shell-polish at 045a7b5.
A37: AT-091 | B37: freezes classification separately from publication audience | C37: 1. Load the source-defined test fixtures. 2. Run this check using the configured repository test runner. 3. Exercise: freezes classification separately from publication audience 4. Verify the test's assertions and side effects. | D37: freezes classification separately from publication audience. All declared source assertions and state checks satisfy the named behavior. | E37: Repository UI test fixtures; component/model mocks and test runner configured as in source. | F37: Passed | H37: Quốc Anh | O37: UI source: packages/ui/tests/knowledgePreviewModel.test.ts:57 Passed on 31 October 2026 in the local run of 387 tests (380 passed, 7 skipped, 0 failed) on feat/workspace-shell-polish at 045a7b5.
A38: AT-092 | B38: resubmits a revised draft as a new pending snapshot without replacing a publication | C38: 1. Load the source-defined test fixtures. 2. Run this check using the configured repository test runner. 3. Exercise: resubmits a revised draft as a new pending snapshot without replacing a publication 4. Verify the test's assertions and side effects. | D38: resubmits a revised draft as a new pending snapshot without replacing a publication. All declared source assertions and state checks satisfy the named behavior. | E38: Repository UI test fixtures; component/model mocks and test runner configured as in source. | F38: Passed | H38: Quốc Anh | O38: UI source: packages/ui/tests/knowledgePreviewModel.test.ts:70 Passed on 31 October 2026 in the local run of 387 tests (380 passed, 7 skipped, 0 failed) on feat/workspace-shell-polish at 045a7b5.
A39: AT-093 | B39: requires a receiving owner for every transfer and revision | C39: 1. Load the source-defined test fixtures. 2. Run this check using the configured repository test runner. 3. Exercise: requires a receiving owner for every transfer and revision 4. Verify the test's assertions and side effects. | D39: requires a receiving owner for every transfer and revision. All declared source assertions and state checks satisfy the named behavior. | E39: Repository UI test fixtures; component/model mocks and test runner configured as in source. | F39: Passed | H39: Quốc Anh | O39: UI source: packages/ui/tests/knowledgePreviewModel.test.ts:89 Passed on 31 October 2026 in the local run of 387 tests (380 passed, 7 skipped, 0 failed) on feat/workspace-shell-polish at 045a7b5.
A40: knowledgeStatus (2)
A41: AT-094 | B41: rejects non-PDF, empty and oversized local files before upload | C41: 1. Load the source-defined test fixtures. 2. Run this check using the configured repository test runner. 3. Exercise: rejects non-PDF, empty and oversized local files before upload 4. Verify the test's assertions and side effects. | D41: rejects non-PDF, empty and oversized local files before upload. Invalid or unauthorized behavior is blocked without a prohibited state change. | E41: Repository UI test fixtures; component/model mocks and test runner configured as in source. | F41: Passed | H41: Quốc Anh | O41: UI source: packages/ui/tests/knowledgeStatus.test.ts:20 Passed on 31 October 2026 in the local run of 387 tests (380 passed, 7 skipped, 0 failed) on feat/workspace-shell-polish at 045a7b5.
A42: AT-095 | B42: distinguishes a published snapshot from a later working version | C42: 1. Load the source-defined test fixtures. 2. Run this check using the configured repository test runner. 3. Exercise: distinguishes a published snapshot from a later working version 4. Verify the test's assertions and side effects. | D42: distinguishes a published snapshot from a later working version. All declared source assertions and state checks satisfy the named behavior. | E42: Repository UI test fixtures; component/model mocks and test runner configured as in source. | F42: Passed | H42: Quốc Anh | O42: UI source: packages/ui/tests/knowledgeStatus.test.ts:28 Passed on 31 October 2026 in the local run of 387 tests (380 passed, 7 skipped, 0 failed) on feat/workspace-shell-polish at 045a7b5.
...

Sheet Feature 3
A2: Feature | B2: UI Workspace | R2: Passed
A3: Test requirement | B3: Workspace shell, application API client, cancellation, navigation and shared UI-contract checks. | R3: Failed
A4: Number of TCs | B4: =COUNTA($F$12:$F$998) -> 35 | R4: Pending
A5: Testing Round | B5: Passed | C5: Failed | D5: Pending | E5: Skipped | R5: Skipped
A6: Round 1 | B6: =COUNTIF($F$12:$F$998,B$5) -> 35 | C6: =COUNTIF($F$12:$F$998,C$5) -> 0 | D6: =COUNTIF($F$12:$F$998,D$5) -> 0 | E6: =COUNTIF($F$12:$F$998,E$5) -> 0
A7: Round 2 | B7: =COUNTIF($I$12:$I$998,B$5) -> 0 | C7: =COUNTIF($I$12:$I$998,C$5) -> 0 | D7: =COUNTIF($I$12:$I$998,D$5) -> 0 | E7: =COUNTIF($I$12:$I$998,E$5) -> 0
A8: Round 3 | B8: =COUNTIF($L$12:$L$998,B$5) -> 0 | C8: =COUNTIF($L$12:$L$998,C$5) -> 0 | D8: =COUNTIF($L$12:$L$998,D$5) -> 0 | E8: =COUNTIF($L$12:$L$998,E$5) -> 0
A10: Test Case ID | B10: Test Case Description | C10: Test Case Procedure | D10: Expected Results | E10: Pre-conditions | F10: Round 1 | G10: Test date | H10: Tester | I10: Round 2 | J10: Test date | K10: Tester | L10: Round 3 | M10: Test date | N10: Tester | O10: Note
A11: apiClient (20)
A12: AT-134 | B12: keeps a lost write response uncertain, without claiming the write failed | C12: 1. Load the source-defined test fixtures. 2. Run this check using the configured repository test runner. 3. Exercise: keeps a lost write response uncertain, without claiming the write failed 4. Verify the test's assertions and side effects. | D12: keeps a lost write response uncertain, without claiming the write failed. The named invariant holds under the exercised input. | E12: Repository UI test fixtures; component/model mocks and test runner configured as in source. | F12: Passed | H12: Quốc Anh | O12: UI source: packages/ui/tests/apiClient.test.ts:26 Passed on 31 October 2026 in the local run of 387 tests (380 passed, 7 skipped, 0 failed) on feat/workspace-shell-polish at 045a7b5.
A13: AT-135 | B13: shows readable document errors while retaining the machine code | C13: 1. Load the source-defined test fixtures. 2. Run this check using the configured repository test runner. 3. Exercise: shows readable document errors while retaining the machine code 4. Verify the test's assertions and side effects. | D13: shows readable document errors while retaining the machine code. Expected UI text, state and presentation appear in the test assertions. | E13: Repository UI test fixtures; component/model mocks and test runner configured as in source. | F13: Passed | H13: Quốc Anh | O13: UI source: packages/ui/tests/apiClient.test.ts:35 Passed on 31 October 2026 in the local run of 387 tests (380 passed, 7 skipped, 0 failed) on feat/workspace-shell-polish at 045a7b5.
A14: AT-136 | B14: uses Arden's sign-in endpoint and HttpOnly web cookies | C14: 1. Load the source-defined test fixtures. 2. Run this check using the configured repository test runner. 3. Exercise: uses Arden's sign-in endpoint and HttpOnly web cookies 4. Verify the test's assertions and side effects. | D14: uses Arden's sign-in endpoint and HttpOnly web cookies. All declared source assertions and state checks satisfy the named behavior. | E14: Repository UI test fixtures; component/model mocks and test runner configured as in source. | F14: Passed | H14: Quốc Anh | O14: UI source: packages/ui/tests/apiClient.test.ts:45 Passed on 31 October 2026 in the local run of 387 tests (380 passed, 7 skipped, 0 failed) on feat/workspace-shell-polish at 045a7b5.
A15: AT-137 | B15: normalizes sessions from an older remote API without account setup state | C15: 1. Load the source-defined test fixtures. 2. Run this check using the configured repository test runner. 3. Exercise: normalizes sessions from an older remote API without account setup state 4. Verify the test's assertions and side effects. | D15: normalizes sessions from an older remote API without account setup state. All declared source assertions and state checks satisfy the named behavior. | E15: Repository UI test fixtures; component/model mocks and test runner configured as in source. | F15: Passed | H15: Quốc Anh | O15: UI source: packages/ui/tests/apiClient.test.ts:59 Passed on 31 October 2026 in the local run of 387 tests (380 passed, 7 skipped, 0 failed) on feat/workspace-shell-polish at 045a7b5.
A16: AT-138 | B16: submits registration through the sign-up endpoint on web | C16: 1. Load the source-defined test fixtures. 2. Run this check using the configured repository test runner. 3. Exercise: submits registration through the sign-up endpoint on web 4. Verify the test's assertions and side effects. | D16: submits registration through the sign-up endpoint on web. All declared source assertions and state checks satisfy the named behavior. | E16: Repository UI test fixtures; component/model mocks and test runner configured as in source. | F16: Passed | H16: Quốc Anh | O16: UI source: packages/ui/tests/apiClient.test.ts:70 Passed on 31 October 2026 in the local run of 387 tests (380 passed, 7 skipped, 0 failed) on feat/workspace-shell-polish at 045a7b5.
A17: AT-139 | B17: fetches invitation preview with encoded token | C17: 1. Load the source-defined test fixtures. 2. Run this check using the configured repository test runner. 3. Exercise: fetches invitation preview with encoded token 4. Verify the test's assertions and side effects. | D17: fetches invitation preview with encoded token. All declared source assertions and state checks satisfy the named behavior. | E17: Repository UI test fixtures; component/model mocks and test runner configured as in source. | F17: Passed | H17: Quốc Anh | O17: UI source: packages/ui/tests/apiClient.test.ts:81 Passed on 31 October 2026 in the local run of 387 tests (380 passed, 7 skipped, 0 failed) on feat/workspace-shell-polish at 045a7b5.
A18: AT-140 | B18: deletes empty department through API client | C18: 1. Load the source-defined test fixtures. 2. Run this check using the configured repository test runner. 3. Exercise: deletes empty department through API client 4. Verify the test's assertions and side effects. | D18: deletes empty department through API client. All declared source assertions and state checks satisfy the named behavior. | E18: Repository UI test fixtures; component/model mocks and test runner configured as in source. | F18: Passed | H18: Quốc Anh | O18: UI source: packages/ui/tests/apiClient.test.ts:93 Passed on 31 October 2026 in the local run of 387 tests (380 passed, 7 skipped, 0 failed) on feat/workspace-shell-polish at 045a7b5.
A19: AT-141 | B19: submits registration through the desktop bridge | C19: 1. Load the source-defined test fixtures. 2. Run this check using the configured repository test runner. 3. Exercise: submits registration through the desktop bridge 4. Verify the test's assertions and side effects. | D19: submits registration through the desktop bridge. All declared source assertions and state checks satisfy the named behavior. | E19: Repository UI test fixtures; component/model mocks and test runner configured as in source. | F19: Passed | H19: Quốc Anh | O19: UI source: packages/ui/tests/apiClient.test.ts:105 Passed on 31 October 2026 in the local run of 387 tests (380 passed, 7 skipped, 0 failed) on feat/workspace-shell-polish at 045a7b5.
A20: AT-142 | B20: keeps desktop cookies inside the secure main-process bridge | C20: 1. Load the source-defined test fixtures. 2. Run this check using the configured repository test runner. 3. Exercise: keeps desktop cookies inside the secure main-process bridge 4. Verify the test's assertions and side effects. | D20: keeps desktop cookies inside the secure main-process bridge. The named invariant holds under the exercised input. | E20: Repository UI test fixtures; component/model mocks and test runner configured as in source. | F20: Passed | H20: Quốc Anh | O20: UI source: packages/ui/tests/apiClient.test.ts:115 Passed on 31 October 2026 in the local run of 387 tests (380 passed, 7 skipped, 0 failed) on feat/workspace-shell-polish at 045a7b5.
A21: AT-143 | B21: finishes desktop Google sign-in through the isolated main-process window | C21: 1. Load the source-defined test fixtures. 2. Run this check using the configured repository test runner. 3. Exercise: finishes desktop Google sign-in through the isolated main-process window 4. Verify the test's assertions and side effects. | D21: finishes desktop Google sign-in through the isolated main-process window. All declared source assertions and state checks satisfy the named behavior. | E21: Repository UI test fixtures; component/model mocks and test runner configured as in source. | F21: Passed | H21: Quốc Anh | O21: UI source: packages/ui/tests/apiClient.test.ts:130 Passed on 31 October 2026 in the local run of 387 tests (380 passed, 7 skipped, 0 failed) on feat/workspace-shell-polish at 045a7b5.
A22: AT-144 | B22: creates the initial Arden password and refreshes the account state | C22: 1. Load the source-defined test fixtures. 2. Run this check using the configured repository test runner. 3. Exercise: creates the initial Arden password and refreshes the account state 4. Verify the test's assertions and side effects. | D22: creates the initial Arden password and refreshes the account state. All declared source assertions and state checks satisfy the named behavior. | E22: Repository UI test fixtures; component/model mocks and test runner configured as in source. | F22: Passed | H22: Quốc Anh | O22: UI source: packages/ui/tests/apiClient.test.ts:139 Passed on 31 October 2026 in the local run of 387 tests (380 passed, 7 skipped, 0 failed) on feat/workspace-shell-polish at 045a7b5.
A23: AT-145 | B23: forwards update versions and clears encrypted desktop sessions after sign-out | C23: 1. Load the source-defined test fixtures. 2. Run this check using the configured repository test runner. 3. Exercise: forwards update versions and clears encrypted desktop sessions after sign-out 4. Verify the test's assertions and side effects. | D23: forwards update versions and clears encrypted desktop sessions after sign-out. All declared source assertions and state checks satisfy the named behavior. | E23: Repository UI test fixtures; component/model mocks and test runner configured as in source. | F23: Passed | H23: Quốc Anh | O23: UI source: packages/ui/tests/apiClient.test.ts:150 Passed on 31 October 2026 in the local run of 387 tests (380 passed, 7 skipped, 0 failed) on feat/workspace-shell-polish at 045a7b5.
