Workbook
Name ACTION: #REF!
Name Z_2C0D9096_8D85_462A_A9B5_0B488ADB4269__wvu_Cols: 'UT-01'!$E:$E
Name Z_2C0D9096_8D85_462A_A9B5_0B488ADB4269__wvu_Cols: 'UT-02'!$E:$E
Name Z_2C0D9096_8D85_462A_A9B5_0B488ADB4269__wvu_Cols: 'UT-03'!$E:$E
Name Z_2C0D9096_8D85_462A_A9B5_0B488ADB4269__wvu_PrintArea: Statistics!$A:$I
Name Z_6F1DCD5D_5DAC_4817_BF40_2B66F6F593E6__wvu_Cols: 'UT-01'!$E:$E
Name Z_6F1DCD5D_5DAC_4817_BF40_2B66F6F593E6__wvu_Cols: 'UT-02'!$E:$E
Name Z_6F1DCD5D_5DAC_4817_BF40_2B66F6F593E6__wvu_Cols: 'UT-03'!$E:$E
Name Z_6F1DCD5D_5DAC_4817_BF40_2B66F6F593E6__wvu_PrintArea: Statistics!$A:$I
Name Z_BE54E0AD_3725_4423_92D7_4F1C045BE1BC__wvu_Cols: 'UT-01'!$E:$E
Name Z_BE54E0AD_3725_4423_92D7_4F1C045BE1BC__wvu_Cols: 'UT-02'!$E:$E
Name Z_BE54E0AD_3725_4423_92D7_4F1C045BE1BC__wvu_Cols: 'UT-03'!$E:$E
Name Z_BE54E0AD_3725_4423_92D7_4F1C045BE1BC__wvu_PrintArea: Statistics!$A:$I

Sheet Guideline
A1: Guideline to make and understand Unit Test Case
A3: 1. Overview
A4: - In the template, Unit test cases are based on functions. Each sheet presents test cases for one function.
A5: - Cover: General information of the project and Unit Test cases
A6: - FunctionList: The list of Classes and Functions in the document. + To control that the number of Unit TC meets customer's requirement or the norm, user should fill value for 'Normal number of Test cases/KLOC'.
A7: + Click on Function link to open the related Test cases of the function. Note: You should create new Function sheet before creating the link
A8: - Test Report: provive the overview results of Functions Unit test: Test coverage, Test successful coverage (Summary, for normal/abnormal/boundary cases)
A9: Note: Should check the formula of "Sub Total" if you add more functions
A11: 2. Content in Test function sheet
A12: 2.1 Combination of test cases.
A13: - To verify that number of Unit TC meets customer's requirement or not. User has to fill number LOC of tested function and fill value of 'Normal number test cases/KLOC' item in FunctionList sheet, which is required by customer or normal value. The number of lacked TC is shown in 'Lack of test cases' item.
A14: - If the number of Unit TC does not meet the requirement, creator should explain the reasons.
... A47: - Test requirement: Brief description about requirements which are tested in this function, it is not mandatory.

Sheet Cover
B2: UNIT TEST DOCUMENT
A4: Project Name | B4: Arden Enterprise Knowledge Platform | E4: Creator | F4: Arden team (assignment pending)
A5: Project Code | B5: ARDEN | E5: Issue Date | F5: 46326
A6: Document Code | B6: ARDEN_UT_v1.2 | E6: Version | F6: 1.2
A9: Record of change
A10: Effective Date | B10: Version | C10: Change Item | D10: *A,D,M | E10: Change description | F10: Reference
A11: 46326 | B11: 1.2 | C11: Unit test cases | D11: M | E11: Updated reporting context: feat/workspace-shell-polish checkout reported 387 tests, 380 passed, seven skipped, zero failed. The 104 curated Unit Test cases retain independent execution fields. | F11: Grok checkout summary supplied by project team (31/10/2026)

Sheet Functions
E2: Function List
A4: Project Name | E4: Arden Enterprise Knowledge Platform
A5: Project Code | E5: ARDEN
A6: Normal number of Test cases/KLOC | E6: N/A
A7: Test Environment Setup Description | E7: Local Node/Vitest test fixtures. Seven live API integration tests were skipped: 1 requires four ARDEN_TEST_SUPABASE_* auth values and 6 require ARDEN_TEST_DATABASE_URL pointing to an isolated superuser-owned arden_test_* PostgreSQL database. Checkout reports 380 passed, 7 skipped, 0 failed; curated FPT cases have no individual run receipt.
A10: No | B10: Requirement Name | C10: Class Name | D10: Function Name | E10: Function Code(Optional) | F10: Sheet Name | G10: Description | H10: Pre-Condition
A11: 1 | B11: Verify active publication audience and member | C11: Core knowledge policy | D11: canReadPublication | E11: UT-001 | F11: =HYPERLINK("#'Function 1'!A1","Function 1") -> Function 1 | G11: 8 concrete test conditions; source apps/api/src/knowledge/policy.test.ts | H11: ACTIVE org, CURRENT publication, fixed time; modify one permission fact per case.
A12: 2 | B12: Enforce live ReviewerGrant and administrator | C12: Core knowledge policy | D12: canReviewSnapshot | E12: UT-002 | F12: =HYPERLINK("#'Function 2'!A1","Function 2") -> Function 2 | G12: 7 concrete test conditions; source apps/api/src/knowledge/policy.test.ts | H12: Active organization reviewer facts, controlled classification and scope.
A13: 3 | B13: Submit only immutable and valid governed snap | C13: Core knowledge policy | D13: canSubmitSnapshot | E13: UT-003 | F13: =HYPERLINK("#'Function3'!A1","Function3") -> Function3 | G13: 7 concrete test conditions; source apps/api/src/knowledge/policy.test.ts | H13: Draft, author membership, responsible department, selected audience.
A14: 4 | B14: Authorize approval, reject stale content and | C14: Core review decision | D14: planReviewDecision | E14: UT-004 | F14: =HYPERLINK("#'UT-04'!A1","UT-04") -> UT-04 | G14: 7 concrete test conditions; source apps/api/src/knowledge/review-decision.test.ts | H14: Fixed review facts, submission snapshot hash, active reviewer grant.
A15: 5 | B15: Show only reviewable pending work and preserv | C15: Core review queue | D15: authorizedReviewQueue | E15: UT-005 | F15: =HYPERLINK("#'UT-05'!A1","UT-05") -> UT-05 | G15: 8 concrete test conditions; source apps/api/src/knowledge/review-queue.test.ts | H15: Pending submissions, live member/grant data and stable ordering.
A16: 6 | B16: Verify index job lease, payload, activation a | C16: Core indexing worker | D16: IndexingWorker.runOnce | E16: UT-006 | F16: =HYPERLINK("#'UT-06'!A1","UT-06") -> UT-06 | G16: 6 concrete test conditions; source apps/api/src/indexing/worker.test.ts | H16: Isolated fake claim store, snapshot, worker client and completion callbacks.
A17: 7 | B17: Maintain opaque URI, integrity hashes and raw | C17: Private content storage | D17: LocalPrivateContentStorage | E17: UT-007 | F17: =HYPERLINK("#'UT-07'!A1","UT-07") -> UT-07 | G17: 6 concrete test conditions; source apps/api/src/private-notes/content-storage.test.ts | H17: Temporary isolated storage root; no production objects.
A18: 8 | B18: Allow only bounded API routes, methods and id | C18: Electron main process | D18: apiRequestPolicy | E18: UT-008 | F18: =HYPERLINK("#'UT-08'!A1","UT-08") -> UT-08 | G18: 7 concrete test conditions; source apps/desktop/src/main/apiRequestPolicy.test.ts | H18: Desktop request policy fixture; bounded payload and route list.
A19: 9 | B19: Preserve canonical IDs, text formatting and s | C19: Shared domain | D19: SemanticDocument v1 parser | E19: UT-009 | F19: =HYPERLINK("#'UT-09'!A1","UT-09") -> UT-09 | G19: 7 concrete test conditions; source packages/domain/src/semantic-document.test.ts | H19: Canonical schema v1 document, serializer and parser.
A20: 10 | B20: Keep unsaved drafts isolated and avoid uninte | C20: UI note draft model | D20: notePreviewReducer | E20: UT-010 | F20: =HYPERLINK("#'UT-10'!A1","UT-10") -> UT-10 | G20: 8 concrete test conditions; source packages/ui/tests/noteDraftModel.test.ts | H20: Sample saved notes, reducer actions and local draft state.
A21: 11 | B21: Apply invitation expiry, status and counting/ | C21: UI organization | D21: invitationState / visibleInvitations | E21: UT-011 | F21: =HYPERLINK("#'UT-11'!A1","UT-11") -> UT-11 | G21: 5 concrete test conditions; source packages/ui/tests/invitationStatus.test.ts | H21: Fixed now 2026-10-23, invitation fixtures.
A22: 12 | B22: Reject nonallowed generation and ungrounded c | C22: Arden-AI answering | D22: PermissionAwareAnswerer.answer | E22: UT-012 | F22: =HYPERLINK("#'UT-12'!A1","UT-12") -> UT-12 | G22: 3 concrete test conditions; source tests/test_answering.py | H22: Fake retriever/generator, UUID allowlist, MFA evidence.
A23: 13 | B23: Preserve chunk offsets, parent section and to | C23: Arden-AI domain | D23: chunk_markdown | E23: UT-013 | F23: =HYPERLINK("#'UT-13'!A1","UT-13") -> UT-13 | G23: 2 concrete test conditions; source tests/test_chunking.py | H23: Compiled semantic document with long security section.
A24: 14 | B24: Validate strict generation payload, hash, PDF | C24: Arden-AI contract | D24: IndexGenerationRequest | E24: UT-014 | F24: =HYPERLINK("#'UT-14'!A1","UT-14") -> UT-14 | G24: 6 concrete test conditions; source tests/test_contracts.py | H24: Versioned camelCase indexing request with stable UUIDs.
A25: 15 | B25: Resolve PDF page from cited block or fallback | C25: Core answer citation | D25: citationPageForSource | E25: UT-015 | F25: =HYPERLINK("#'UT-15'!A1","UT-15") -> UT-15 | G25: 3 concrete test conditions; source apps/api/src/answers/citation-page.test.ts | H25: Cited semantic source blocks and optional parent reference.
A26: 16 | B26: Filter managed audience by scope and disallow | C26: UI knowledge audience | D26: knowledgeAudience selection | E26: UT-016 | F26: =HYPERLINK("#'UT-16'!A1","UT-16") -> UT-16 | G26: 3 concrete test conditions; source packages/ui/tests/knowledgeAudience.test.ts | H26: Org and department audience fixtures plus selected scope.
A27: 17 | B27: Constrain synthetic account, DB target and re | C27: Local test authentication | D27: LocalFlow1TestAuthProvider | E27: UT-017 | F27: =HYPERLINK("#'UT-17'!A1","UT-17") -> UT-17 | G27: 6 concrete test conditions; source apps/api/src/auth/local-flow1-test.test.ts | H27: Isolated loopback test DB; example.test fixtures only.
A28: 18 | B28: Use correct citation page and safe download n | C28: UI PDF preview | D28: PDF viewer identity | E28: UT-018 | F28: =HYPERLINK("#'UT-18'!A1","UT-18") -> UT-18 | G28: 2 concrete test conditions; source packages/ui/tests/pdfDocument.test.ts | H28: Synthetic PDF id, citation page and document metadata.
A29: 19 | B29: Validate digest, snapshot identity and strict | C29: Core indexing contract | D29: IndexGenerationManifest validator | E29: UT-019 | F29: =HYPERLINK("#'UT-19'!A1","UT-19") -> UT-19 | G29: 3 concrete test conditions; source apps/api/src/indexing/contracts.test.ts | H29: Expected Core snapshot identity and response manifest.

Sheet Statistics
A2: UNIT TEST REPORT
A4: Project Name | B4: Arden Enterprise Knowledge Platform | D4: Creator | F4: Arden team (TBD)
A5: Project Code | B5: ARDEN | D5: Reviewer/Approver | F5: TBD
A6: Document Code | B6: ARDEN_UT_Report_v1.2 | D6: Issue Date | F6: 46326
A7: Notes | B7: Checkout: 380 passed, 7 skipped, 0 failed / 387 total. The 104 unit cases have no per-case results.
A11: No | B11: Function code | C11: Passed | D11: Failed | E11: Untested | F11: N | G11: A | H11: B | I11: Total Test Cases | K11: Type | L11: Count | M11: Result | N11: Count
A12: 1 | B12: =Functions!E11 -> UT-001 | C12: ='UT-01'!A7 -> 0 | D12: ='UT-01'!C7 -> 0 | E12: ='UT-01'!F7 -> 8 | F12: ='UT-01'!L7 -> 2 | G12: ='UT-01'!M7 -> 5 | H12: ='UT-01'!N7 -> 1 | I12: ='UT-01'!O7 -> 8 | K12: N | L12: =F33 -> 41 | M12: Passed | N12: =C33 -> 0
A13: 2 | B13: =Functions!E12 -> UT-002 | C13: ='UT-02'!A7 -> 0 | D13: ='UT-02'!C7 -> 0 | E13: ='UT-02'!F7 -> 7 | F13: ='UT-02'!L7 -> 3 | G13: ='UT-02'!M7 -> 2 | H13: ='UT-02'!N7 -> 2 | I13: ='UT-02'!O7 -> 7 | K13: A | L13: =G33 -> 39 | M13: Failed | N13: =D33 -> 0
A14: 3 | B14: =Functions!E13 -> UT-003 | C14: ='UT-03'!A7 -> 0 | D14: ='UT-03'!C7 -> 0 | E14: ='UT-03'!F7 -> 7 | F14: ='UT-03'!L7 -> 3 | G14: ='UT-03'!M7 -> 3 | H14: ='UT-03'!N7 -> 1 | I14: ='UT-03'!O7 -> 7 | K14: B | L14: =H33 -> 24 | M14: Untested | N14: =E33 -> 104
A15: 4 | B15: =Functions!E14 -> UT-004 | C15: ='UT-04'!A7 -> 0 | D15: ='UT-04'!C7 -> 0 | E15: ='UT-04'!F7 -> 7 | F15: ='UT-04'!L7 -> 2 | G15: ='UT-04'!M7 -> 4 | H15: ='UT-04'!N7 -> 1 | I15: ='UT-04'!O7 -> 7
A16: 5 | B16: =Functions!E15 -> UT-005 | C16: ='UT-05'!A7 -> 0 | D16: ='UT-05'!C7 -> 0 | E16: ='UT-05'!F7 -> 8 | F16: ='UT-05'!L7 -> 2 | G16: ='UT-05'!M7 -> 3 | H16: ='UT-05'!N7 -> 3 | I16: ='UT-05'!O7 -> 8
A17: 6 | B17: =Functions!E16 -> UT-006 | C17: ='UT-06'!A7 -> 0 | D17: ='UT-06'!C7 -> 0 | E17: ='UT-06'!F7 -> 6 | F17: ='UT-06'!L7 -> 3 | G17: ='UT-06'!M7 -> 1 | H17: ='UT-06'!N7 -> 2 | I17: ='UT-06'!O7 -> 6 | K17: Checkout | L17: Passed | M17: Skipped
A18: 7 | B18: =Functions!E17 -> UT-007 | C18: ='UT-07'!A7 -> 0 | D18: ='UT-07'!C7 -> 0 | E18: ='UT-07'!F7 -> 6 | F18: ='UT-07'!L7 -> 2 | G18: ='UT-07'!M7 -> 3 | H18: ='UT-07'!N7 -> 1 | I18: ='UT-07'!O7 -> 6 | K18: UI | L18: 168 | M18: 0
A19: 8 | B19: =Functions!E18 -> UT-008 | C19: ='UT-08'!A7 -> 0 | D19: ='UT-08'!C7 -> 0 | E19: ='UT-08'!F7 -> 7 | F19: ='UT-08'!L7 -> 4 | G19: ='UT-08'!M7 -> 2 | H19: ='UT-08'!N7 -> 1 | I19: ='UT-08'!O7 -> 7 | K19: API | L19: 136 | M19: 7
A20: 9 | B20: =Functions!E19 -> UT-009 | C20: ='UT-09'!A7 -> 0 | D20: ='UT-09'!C7 -> 0 | E20: ='UT-09'!F7 -> 7 | F20: ='UT-09'!L7 -> 1 | G20: ='UT-09'!M7 -> 5 | H20: ='UT-09'!N7 -> 1 | I20: ='UT-09'!O7 -> 7 | K20: Desktop | L20: 7 | M20: 0
A21: 10 | B21: =Functions!E20 -> UT-010 | C21: ='UT-10'!A7 -> 0 | D21: ='UT-10'!C7 -> 0 | E21: ='UT-10'!F7 -> 8 | F21: ='UT-10'!L7 -> 5 | G21: ='UT-10'!M7 -> 1 | H21: ='UT-10'!N7 -> 2 | I21: ='UT-10'!O7 -> 8 | K21: Domain | L21: 5 | M21: 0
A22: 11 | B22: =Functions!E21 -> UT-011 | C22: ='UT-11'!A7 -> 0 | D22: ='UT-11'!C7 -> 0 | E22: ='UT-11'!F7 -> 5 | F22: ='UT-11'!L7 -> 2 | G22: ='UT-11'!M7 -> 1 | H22: ='UT-11'!N7 -> 2 | I22: ='UT-11'!O7 -> 5 | K22: Remote | L22: 16 | M22: 0
A23: 12 | B23: =Functions!E22 -> UT-012 | C23: ='UT-12'!A7 -> 0 | D23: ='UT-12'!C7 -> 0 | E23: ='UT-12'!F7 -> 3 | F23: ='UT-12'!L7 -> 1 | G23: ='UT-12'!M7 -> 1 | H23: ='UT-12'!N7 -> 1 | I23: ='UT-12'!O7 -> 3 | K23: Release/PR | L23: 48 | M23: 0
A24: 13 | B24: =Functions!E23 -> UT-013 | C24: ='UT-13'!A7 -> 0 | D24: ='UT-13'!C7 -> 0 | E24: ='UT-13'!F7 -> 2 | F24: ='UT-13'!L7 -> 1 | G24: ='UT-13'!M7 -> 0 | H24: ='UT-13'!N7 -> 1 | I24: ='UT-13'!O7 -> 2 | K24: TOTAL | L24: 380 | M24: 7
A25: 14 | B25: =Functions!E24 -> UT-014 | C25: ='UT-14'!A7 -> 0 | D25: ='UT-14'!C7 -> 0 | E25: ='UT-14'!F7 -> 6 | F25: ='UT-14'!L7 -> 3 | G25: ='UT-14'!M7 -> 2 | H25: ='UT-14'!N7 -> 1 | I25: ='UT-14'!O7 -> 6
A26: 15 | B26: =Functions!E25 -> UT-015 | C26: ='UT-15'!A7 -> 0 | D26: ='UT-15'!C7 -> 0 | E26: ='UT-15'!F7 -> 3 | F26: ='UT-15'!L7 -> 1 | G26: ='UT-15'!M7 -> 1 | H26: ='UT-15'!N7 -> 1 | I26: ='UT-15'!O7 -> 3
A27: 16 | B27: =Functions!E26 -> UT-016 | C27: ='UT-16'!A7 -> 0 | D27: ='UT-16'!C7 -> 0 | E27: ='UT-16'!F7 -> 3 | F27: ='UT-16'!L7 -> 1 | G27: ='UT-16'!M7 -> 1 | H27: ='UT-16'!N7 -> 1 | I27: ='UT-16'!O7 -> 3
A28: 17 | B28: =Functions!E27 -> UT-017 | C28: ='UT-17'!A7 -> 0 | D28: ='UT-17'!C7 -> 0 | E28: ='UT-17'!F7 -> 6 | F28: ='UT-17'!L7 -> 2 | G28: ='UT-17'!M7 -> 3 | H28: ='UT-17'!N7 -> 1 | I28: ='UT-17'!O7 -> 6
A29: 18 | B29: =Functions!E28 -> UT-018 | C29: ='UT-18'!A7 -> 0 | D29: ='UT-18'!C7 -> 0 | E29: ='UT-18'!F7 -> 2 | F29: ='UT-18'!L7 -> 1 | G29: ='UT-18'!M7 -> 0 | H29: ='UT-18'!N7 -> 1 | I29: ='UT-18'!O7 -> 2
A30: 19 | B30: =Functions!E29 -> UT-019 | C30: ='UT-19'!A7 -> 0 | D30: ='UT-19'!C7 -> 0 | E30: ='UT-19'!F7 -> 3 | F30: ='UT-19'!L7 -> 2 | G30: ='UT-19'!M7 -> 1 | H30: ='UT-19'!N7 -> 0 | I30: ='UT-19'!O7 -> 3
B33: Sub total | C33: =SUM(C12:C30) -> 0 | D33: =SUM(D12:D30) -> 0 | E33: =SUM(E12:E30) -> 104 | F33: =SUM(F12:F30) -> 41 | G33: =SUM(G12:G30) -> 39 | H33: =SUM(H12:H30) -> 24 | I33: =SUM(I12:I30) -> 104
B35: Test coverage | D35: =IFERROR((C33+D33)*100/I33,0) -> 0 | E35: %
B36: Test successful coverage | D36: =IFERROR((C33)*100/I33,0) -> 0 | E36: %
B37: Normal case | D37: =IFERROR((F33)*100/I33,0) -> 39.423077 | E37: %
B38: Abnormal case | D38: =IFERROR((G33)*100/I33,0) -> 37.5 | E38: %
B39: Boundary case | D39: =IFERROR((H33)*100/I33,0) -> 23.076923 | E39: %

Sheet Example
A2: Function Code | C2: NOT COUNTED | F2: Function Name | L2: Blank template example
A3: Created By | C3: TBD | F3: Executed By
A4: Lines of code | F4: Lack of test cases | L4: =IF(Functions!E6<>"N/A",SUM(C4*Functions!E6/1000,-O7),"N/A") -> N/A
A5: Test requirement | C5: Fill inputs and confirmations on Arden function sheets. No sample outcomes are project results.
A6: Passed | C6: Failed | F6: Untested | L6: N/A/B | O6: Total Test Cases
A7: =COUNTIF(F47:HQ47,"P") -> 0 | C7: =COUNTIF(F47:HQ47,"F") -> 0 | F7: =SUM(O7,-A7,-C7) -> 0 | L7: =COUNTIF(E46:HQ46,"N") -> 0 | M7: =COUNTIF(E46:HQ46,"A") -> 0 | N7: =COUNTIF(E46:HQ46,"B") -> 0 | O7: =COUNTA(E9:HT9) -> 0
A10: Condition | B10: Precondition
B14: a
B19: b
B23: c
A33: Confirm | B33: Return
B34: list
B40: Exception
B42: Log message
A45: Result | B45: Type(N : Normal, A : Abnormal, B : Boundary)
B46: Passed/Failed
B47: Executed Date
B48: Defect ID

Sheet UT-01
A2: Function Code | C2: =Functions!E11 -> UT-001 | F2: Function Name | L2: =Functions!D11 -> canReadPublication
A3: Created By | C3: Khôi | F3: Executed By | L3: Quốc Anh
A4: Lines of code | C4: 21 | F4: Lack of test cases | L4: =IF(OR(Functions!E6="N/A",C4=""),"N/A",MAX(0,ROUNDUP(C4*Functions!E6/1000,0)-O7)) -> N/A
A5: Test requirement | C5: Verify active publication audience and member visibility.
A6: Passed | C6: Failed | F6: Untested | L6: N/A/B | O6: Total Test Cases
A7: =COUNTIF(F40:T40,"P") -> 0 | C7: =COUNTIF(F40:T40,"F") -> 0 | F7: =MAX(0,O7-A7-C7) -> 8 | L7: =COUNTIF(F39:T39,"N") -> 2 | M7: =COUNTIF(F39:T39,"A") -> 5 | N7: =COUNTIF(F39:T39,"B") -> 1 | O7: =COUNTA(F9:T9) -> 8
F9: 01 | G9: 02 | H9: 03 | I9: 04 | J9: 05 | K9: 06 | L9: 07 | M9: 08
A10: Condition | B10: Precondition
B11: ACTIVE org, CURRENT publication, fixed time; modify one permission fact per case. | F11: O | G11: O | H11: O | I11: O | J11: O | K11: O | L11: O | M11: O
B14: Inputs / scenarios
B15: ACTIVE group member | F15: O
B16: No group membership | G16: O
B17: REVOKED group membership | H17: O
B18: SUSPENDED actor | I18: O
B19: CURRENT pointer; legacy dates inverted | J19: O
B20: ORGANIZATION_ALL audience; org matches | K20: O
B21: DEPARTMENT_ALL audience; wrong department | L21: O
B22: Reviewer role without reader scope | M22: O
A31: Confirm | B31: Confirm
B32: true: readable | F32: O | K32: O
B33: false: denied | G33: O | H33: O | I33: O | L33: O | M33: O
B34: true: current pointer wins | J34: O
A39: Result | B39: Type(N : Normal, A : Abnormal, B : Boundary) | F39: N | G39: A | H39: A | I39: A | J39: B | K39: N | L39: A | M39: A
B40: Passed/Failed
B41: Executed Date
B42: Defect ID
A44: PRECONDITION: ACTIVE org, CURRENT publication, fixed time; modify one permission fact per case. | SOURCE: Arden/apps/api/src/knowledge/policy.test.ts | SHA: 953be5418f5489f14cb01c919cb649c207637ec9
A45: Case ID | B45: Exact source test declaration | K45: Input / expected confirmation
A46: U01-01 | B46: reads a group publication only for an active group member | K46: ACTIVE group member → true: readable
A47: U01-02 | B47: reads a group publication only for an active group member | K47: No group membership → false: denied
A48: U01-03 | B48: reads a group publication only for an active group member | K48: REVOKED group membership → false: denied
A49: U01-04 | B49: reads a group publication only for an active group member | K49: SUSPENDED actor → false: denied
A50: U01-05 | B50: uses the active pointer rather than legacy publication dates | K50: CURRENT pointer; legacy dates inverted → true: current pointer wins
A51: U01-06 | B51: applies managed organization and department audiences only at their matching scope | K51: ORGANIZATION_ALL audience; org matches → true: readable
A52: U01-07 | B52: applies managed organization and department audiences only at their matching scope | K52: DEPARTMENT_ALL audience; wrong department → false: denied
A53: U01-08 | B53: does not turn review or administration into publication readership | K53: Reviewer role without reader scope → false: denied

Sheet UT-02
A2: Function Code | C2: =Functions!E12 -> UT-002 | F2: Function Name | L2: =Functions!D12 -> canReviewSnapshot
A3: Created By | C3: Khôi | F3: Executed By | L3: Quốc Anh
A4: Lines of code | C4: 12 | F4: Lack of test cases | L4: =IF(OR(Functions!E6="N/A",C4=""),"N/A",MAX(0,ROUNDUP(C4*Functions!E6/1000,0)-O7)) -> N/A
A5: Test requirement | C5: Enforce live ReviewerGrant and administrator exception.
A6: Passed | C6: Failed | F6: Untested | L6: N/A/B | O6: Total Test Cases
A7: =COUNTIF(F40:T40,"P") -> 0 | C7: =COUNTIF(F40:T40,"F") -> 0 | F7: =MAX(0,O7-A7-C7) -> 7 | L7: =COUNTIF(F39:T39,"N") -> 3 | M7: =COUNTIF(F39:T39,"A") -> 2 | N7: =COUNTIF(F39:T39,"B") -> 2 | O7: =COUNTA(F9:T9) -> 7
F9: 01 | G9: 02 | H9: 03 | I9: 04 | J9: 05 | K9: 06 | L9: 07
A10: Condition | B10: Precondition
B11: Active organization reviewer facts, controlled classification and scope. | F11: O | G11: O | H11: O | I11: O | J11: O | K11: O | L11: O
B14: Inputs / scenarios
B15: Ordinary reviewer with live matching grant | F15: O
B16: Author reviews own ordinary submission | G16: O
B17: Restricted class; no specialist level | H17: O
B18: Org Admin self-review, no grant | I18: O
B19: Dept reviewer on own department snapshot | J19: O
B20: Expired reviewer grant | K20: O
B21: Org Admin final authority | L21: O
A31: Confirm | B31: Confirm
B32: true: authorized | F32: O | J32: O | L32: O
B33: false: denied | G33: O | H33: O | K33: O
B34: true: admin exception | I34: O
A39: Result | B39: Type(N : Normal, A : Abnormal, B : Boundary) | F39: N | G39: A | H39: A | I39: B | J39: N | K39: B | L39: N
B40: Passed/Failed
B41: Executed Date
B42: Defect ID
A44: PRECONDITION: Active organization reviewer facts, controlled classification and scope. | SOURCE: Arden/apps/api/src/knowledge/policy.test.ts | SHA: 953be5418f5489f14cb01c919cb649c207637ec9
A45: Case ID | B45: Exact source test declaration | K45: Input / expected confirmation
A46: U02-01 | B46: uses ReviewerGrant, denies self-review, and requires specialist level for Restricted | K46: Ordinary reviewer with live matching grant → true: authorized
A47: U02-02 | B47: uses ReviewerGrant, denies self-review, and requires specialist level for Restricted | K47: Author reviews own ordinary submission → false: denied
A48: U02-03 | B48: uses ReviewerGrant, denies self-review, and requires specialist level for Restricted | K48: Restricted class; no specialist level → false: denied
A49: U02-04 | B49: allows Organization Admin to review and self-approve without a reviewer grant | K49: Org Admin self-review, no grant → true: admin exception
A50: U02-05 | B50: lets a department reviewer decide a department or group-limited snapshot | K50: Dept reviewer on own department snapshot → true: authorized
A51: U02-06 | B51: rechecks expiry, tags and ordinary self-review for an organization grant | K51: Expired reviewer grant → false: denied
A52: U02-07 | B52: keeps Organization Admin final authority from decision 0011 | K52: Org Admin final authority → true: authorized

Sheet UT-03
A2: Function Code | C2: =Functions!E13 -> UT-003 | F2: Function Name | L2: =Functions!D13 -> canSubmitSnapshot
A3: Created By | C3: Khôi | F3: Executed By | L3: Quốc Anh
A4: Lines of code | C4: 16 | F4: Lack of test cases | L4: =IF(OR(Functions!E6="N/A",C4=""),"N/A",MAX(0,ROUNDUP(C4*Functions!E6/1000,0)-O7)) -> N/A
A5: Test requirement | C5: Submit only immutable and valid governed snapshots.
A6: Passed | C6: Failed | F6: Untested | L6: N/A/B | O6: Total Test Cases
A7: =COUNTIF(F40:T40,"P") -> 0 | C7: =COUNTIF(F40:T40,"F") -> 0 | F7: =MAX(0,O7-A7-C7) -> 7 | L7: =COUNTIF(F39:T39,"N") -> 3 | M7: =COUNTIF(F39:T39,"A") -> 3 | N7: =COUNTIF(F39:T39,"B") -> 1 | O7: =COUNTA(F9:T9) -> 7
F9: 01 | G9: 02 | H9: 03 | I9: 04 | J9: 05 | K9: 06 | L9: 07
A10: Condition | B10: Precondition
B11: Draft, author membership, responsible department, selected audience. | F11: O | G11: O | H11: O | I11: O | J11: O | K11: O | L11: O
B14: Inputs / scenarios
B15: Immutable snapshot and enforceable audience | F15: O
B16: Audience is unenforceable | G16: O
B17: Responsible department = author department | H17: O
B18: Different department chosen | I18: O
B19: Disjoint scopes in submission | J19: O
B20: Breadth not explicitly LIMITED | K20: O
B21: Legacy organization-wide submission | L21: O
A31: Confirm | B31: Confirm
B32: true: can submit | F32: O | H32: O
B33: false: denied | G33: O | I33: O | K33: O
B34: true: correct scope | J34: O
B35: legacy transition allowed | L35: O
A39: Result | B39: Type(N : Normal, A : Abnormal, B : Boundary) | F39: N | G39: A | H39: N | I39: A | J39: N | K39: A | L39: B
B40: Passed/Failed
B41: Executed Date
B42: Defect ID
A44: PRECONDITION: Draft, author membership, responsible department, selected audience. | SOURCE: Arden/apps/api/src/knowledge/policy.test.ts | SHA: 953be5418f5489f14cb01c919cb649c207637ec9
A45: Case ID | B45: Exact source test declaration | K45: Input / expected confirmation
A46: U03-01 | B46: submits only an immutable, enforceable audience snapshot | K46: Immutable snapshot and enforceable audience → true: can submit
A47: U03-02 | B47: submits only an immutable, enforceable audience snapshot | K47: Audience is unenforceable → false: denied
A48: U03-03 | B48: submits only when the responsible department is the author | K48: Responsible department = author department → true: can submit
A49: U03-04 | B49: derives the responsible department from the author and rejects any other department (decision 0014) | K49: Different department chosen → false: denied
A50: U03-05 | B50: uses disjoint scopes for new submissions | K50: Disjoint scopes in submission → true: correct scope
A51: U03-06 | B51: fails closed when the breadth is not an explicit LIMITED value | K51: Breadth not explicitly LIMITED → false: denied
A52: U03-07 | B52: keeps the transition path for legacy organization-wide submissions | K52: Legacy organization-wide submission → legacy transition allowed

Sheet UT-04
A2: Function Code | C2: =Functions!E14 -> UT-004 | F2: Function Name | L2: =Functions!D14 -> planReviewDecision
A3: Created By | C3: Khôi | F3: Executed By | L3: Quốc Anh
A4: Lines of code | C4: 53 | F4: Lack of test cases | L4: =IF(OR(Functions!E6="N/A",C4=""),"N/A",MAX(0,ROUNDUP(C4*Functions!E6/1000,0)-O7)) -> N/A
A5: Test requirement | C5: Authorize approval, reject stale content and avoid early publication.
A6: Passed | C6: Failed | F6: Untested | L6: N/A/B | O6: Total Test Cases
A7: =COUNTIF(F40:T40,"P") -> 0 | C7: =COUNTIF(F40:T40,"F") -> 0 | F7: =MAX(0,O7-A7-C7) -> 7 | L7: =COUNTIF(F39:T39,"N") -> 2 | M7: =COUNTIF(F39:T39,"A") -> 4 | N7: =COUNTIF(F39:T39,"B") -> 1 | O7: =COUNTA(F9:T9) -> 7
F9: 01 | G9: 02 | H9: 03 | I9: 04 | J9: 05 | K9: 06 | L9: 07
A10: Condition | B10: Precondition
B11: Fixed review facts, submission snapshot hash, active reviewer grant. | F11: O | G11: O | H11: O | I11: O | J11: O | K11: O | L11: O
B14: Inputs / scenarios
B15: Final authorized one-step APPROVE | F15: O
B16: Wrong snapshot version | G16: O
B17: Content hash changed | H17: O
B18: Inactive or mismatched grant | I18: O
B19: Unenforceable audience | J19: O
B20: REJECT with reason | K20: O
B21: Org Admin self-approves | L21: O
A31: Confirm | B31: Confirm
B32: publication preparation intent | F32: O
B33: DENIED: STALE_SNAPSHOT | G33: O | H33: O
B34: DENIED: NOT_AUTHORIZED | I34: O
B35: DENIED | J35: O
B36: no publication intent | K36: O
B37: authorized admin exception | L37: O
A39: Result | B39: Type(N : Normal, A : Abnormal, B : Boundary) | F39: N | G39: A | H39: A | I39: A | J39: A | K39: N | L39: B
B40: Passed/Failed
B41: Executed Date
B42: Defect ID
A44: PRECONDITION: Fixed review facts, submission snapshot hash, active reviewer grant. | SOURCE: Arden/apps/api/src/knowledge/review-decision.test.ts | SHA: 953be5418f5489f14cb01c919cb649c207637ec9
A45: Case ID | B45: Exact source test declaration | K45: Input / expected confirmation
A46: U04-01 | B46: plans publication preparation only for an authorized final one-step approval | K46: Final authorized one-step APPROVE → publication preparation intent
A47: U04-02 | B47: never publishes the wrong or corrupted snapshot | K47: Wrong snapshot version → DENIED: STALE_SNAPSHOT
A48: U04-03 | B48: never publishes the wrong or corrupted snapshot | K48: Content hash changed → DENIED: STALE_SNAPSHOT
A49: U04-04 | B49: rechecks identity, active grant, department, policy and self-review | K49: Inactive or mismatched grant → DENIED: NOT_AUTHORIZED
A50: U04-05 | B50: blocks approval for unenforceable audience or unsupported multi-step policy | K50: Unenforceable audience → DENIED
A51: U04-06 | B51: allows rejection with a reason but never emits publication intent | K51: REJECT with reason → no publication intent
A52: U04-07 | B52: allows Organization Admin self-approval without a reviewer grant | K52: Org Admin self-approves → authorized admin exception

Sheet UT-05
A2: Function Code | C2: =Functions!E15 -> UT-005 | F2: Function Name | L2: =Functions!D15 -> authorizedReviewQueue
A3: Created By | C3: Hưng | F3: Executed By | L3: Quốc Anh
A4: Lines of code | C4: 39 | F4: Lack of test cases | L4: =IF(OR(Functions!E6="N/A",C4=""),"N/A",MAX(0,ROUNDUP(C4*Functions!E6/1000,0)-O7)) -> N/A
A5: Test requirement | C5: Show only reviewable pending work and preserve rejectable invalid submissions.
A6: Passed | C6: Failed | F6: Untested | L6: N/A/B | O6: Total Test Cases
A7: =COUNTIF(F40:T40,"P") -> 0 | C7: =COUNTIF(F40:T40,"F") -> 0 | F7: =MAX(0,O7-A7-C7) -> 8 | L7: =COUNTIF(F39:T39,"N") -> 2 | M7: =COUNTIF(F39:T39,"A") -> 3 | N7: =COUNTIF(F39:T39,"B") -> 3 | O7: =COUNTA(F9:T9) -> 8
F9: 01 | G9: 02 | H9: 03 | I9: 04 | J9: 05 | K9: 06 | L9: 07 | M9: 08
A10: Condition | B10: Precondition
B11: Pending submissions, live member/grant data and stable ordering. | F11: O | G11: O | H11: O | I11: O | J11: O | K11: O | L11: O | M11: O
B14: Inputs / scenarios
B15: Live matching reviewer | F15: O
B16: Invalid-audience submission | G16: O
B17: Org Admin own pending submission | H17: O
B18: Live matching classification/team grant | I18: O
B19: Restricted without specialist | J19: O
B20: Org-wide submission; department reviewer | K20: O
B21: Inactive reviewer or malformed policy data | L21: O
B22: Duplicate joins and newer submissions | M22: O
A31: Confirm | B31: Confirm
B32: only authorized pending rows | F32: O
B33: remains visible to reject | G33: O
B34: visible without grant | H34: O
B35: visible | I35: O
B36: hidden | J36: O | K36: O
B37: fail closed | L37: O
B38: deduped newest first | M38: O
A39: Result | B39: Type(N : Normal, A : Abnormal, B : Boundary) | F39: N | G39: B | H39: B | I39: N | J39: A | K39: A | L39: A | M39: B
B40: Passed/Failed
B41: Executed Date
B42: Defect ID
A44: PRECONDITION: Pending submissions, live member/grant data and stable ordering. | SOURCE: Arden/apps/api/src/knowledge/review-queue.test.ts | SHA: 953be5418f5489f14cb01c919cb649c207637ec9
A45: Case ID | B45: Exact source test declaration | K45: Input / expected confirmation
A46: U05-01 | B46: returns only currently authorized pending submissions | K46: Live matching reviewer → only authorized pending rows
A47: U05-02 | B47: keeps an invalid-audience submission visible so the reviewer can reject it | K47: Invalid-audience submission → remains visible to reject
A48: U05-03 | B48: shows Organization Admin their own pending submission without a reviewer grant | K48: Org Admin own pending submission → visible without grant
A49: U05-04 | B49: accepts one matching live grant, including classification and attribute filters | K49: Live matching classification/team grant → visible
A50: U05-05 | B50: requires a specialist or senior grant for restricted material | K50: Restricted without specialist → hidden
A51: U05-06 | B51: shows an organization-wide submission only to an organization reviewer | K51: Org-wide submission; department reviewer → hidden
A52: U05-07 | B52: fails closed for inactive actors and invalid queue data | K52: Inactive reviewer or malformed policy data → fail closed
A53: U05-08 | B53: deduplicates join results after authorization and sorts newest first | K53: Duplicate joins and newer submissions → deduped newest first

Sheet UT-06
A2: Function Code | C2: =Functions!E16 -> UT-006 | F2: Function Name | L2: =Functions!D16 -> IndexingWorker.runOnce
A3: Created By | C3: Quốc Anh | F3: Executed By | L3: Quốc Anh
A4: Lines of code | C4: 22 | F4: Lack of test cases | L4: =IF(OR(Functions!E6="N/A",C4=""),"N/A",MAX(0,ROUNDUP(C4*Functions!E6/1000,0)-O7)) -> N/A
A5: Test requirement | C5: Verify index job lease, payload, activation and no-job behavior.
A6: Passed | C6: Failed | F6: Untested | L6: N/A/B | O6: Total Test Cases
A7: =COUNTIF(F40:T40,"P") -> 0 | C7: =COUNTIF(F40:T40,"F") -> 0 | F7: =MAX(0,O7-A7-C7) -> 6 | L7: =COUNTIF(F39:T39,"N") -> 3 | M7: =COUNTIF(F39:T39,"A") -> 1 | N7: =COUNTIF(F39:T39,"B") -> 2 | O7: =COUNTA(F9:T9) -> 6
F9: 01 | G9: 02 | H9: 03 | I9: 04 | J9: 05 | K9: 06
A10: Condition | B10: Precondition
B11: Isolated fake claim store, snapshot, worker client and completion callbacks. | F11: O | G11: O | H11: O | I11: O | J11: O | K11: O
B14: Inputs / scenarios
B15: Lease 300s default | F15: O
B16: Lease shorter than request margin | G16: O
B17: Superseded generation on complete | H17: O
B18: One ready semantic snapshot job | I18: O
B19: Integrity-checked PDF snapshot | J19: O
B20: No ready job | K20: O
A31: Confirm | B31: Confirm
B32: returns 300 seconds | F32: O
B33: throws config error | G33: O
B34: nonretryable superseded failure | H34: O
B35: indexes; complete activates atomically | I35: O
B36: base64 payload roundtrips | J36: O
B37: idle without side effects | K37: O
A39: Result | B39: Type(N : Normal, A : Abnormal, B : Boundary) | F39: N | G39: B | H39: A | I39: N | J39: N | K39: B
B40: Passed/Failed
B41: Executed Date
B42: Defect ID
A44: PRECONDITION: Isolated fake claim store, snapshot, worker client and completion callbacks. | SOURCE: Arden/apps/api/src/indexing/worker.test.ts | SHA: 953be5418f5489f14cb01c919cb649c207637ec9
A45: Case ID | B45: Exact source test declaration | K45: Input / expected confirmation
A46: U06-01 | B46: rejects leases shorter than the bounded AI request plus completion margin | K46: Lease 300s default → returns 300 seconds
A47: U06-02 | B47: rejects leases shorter than the bounded AI request plus completion margin | K47: Lease shorter than request margin → throws config error
A48: U06-03 | B48: does not retry a generation superseded by an already published snapshot | K48: Superseded generation on complete → nonretryable superseded failure
A49: U06-04 | B49: indexes one claimed snapshot and delegates atomic activation to core storage | K49: One ready semantic snapshot job → indexes; complete activates atomically
A50: U06-05 | B50: passes an integrity-checked PDF snapshot to Arden AI as base64 | K50: Integrity-checked PDF snapshot → base64 payload roundtrips
A51: U06-06 | B51: returns idle without side effects when no job is ready | K51: No ready job → idle without side effects

Sheet UT-07
A2: Function Code | C2: =Functions!E17 -> UT-007 | F2: Function Name | L2: =Functions!D17 -> LocalPrivateContentStorage
A3: Created By | C3: Kiệt | F3: Executed By | L3: Quốc Anh
A4: Lines of code | C4: 89 | F4: Lack of test cases | L4: =IF(OR(Functions!E6="N/A",C4=""),"N/A",MAX(0,ROUNDUP(C4*Functions!E6/1000,0)-O7)) -> N/A
A5: Test requirement | C5: Maintain opaque URI, integrity hashes and raw PDF bytes.
A6: Passed | C6: Failed | F6: Untested | L6: N/A/B | O6: Total Test Cases
A7: =COUNTIF(F40:T40,"P") -> 0 | C7: =COUNTIF(F40:T40,"F") -> 0 | F7: =MAX(0,O7-A7-C7) -> 6 | L7: =COUNTIF(F39:T39,"N") -> 2 | M7: =COUNTIF(F39:T39,"A") -> 3 | N7: =COUNTIF(F39:T39,"B") -> 1 | O7: =COUNTA(F9:T9) -> 6
F9: 01 | G9: 02 | H9: 03 | I9: 04 | J9: 05 | K9: 06
A10: Condition | B10: Precondition
B11: Temporary isolated storage root; no production objects. | F11: O | G11: O | H11: O | I11: O | J11: O | K11: O
B14: Inputs / scenarios
B15: Store and read Unicode text | F15: O
B16: Read with incorrect SHA-256 | G16: O
B17: Path traversal reference | H17: O
B18: Delete opaque object, read again | I18: O
B19: Store PDF bytes; readPdf | J19: O
B20: Read PDF as text | K20: O
A31: Confirm | B31: Confirm
B32: roundtrip; hash verified | F32: O
B33: integrity check failure | G33: O
B34: invalid private URI | H34: O
B35: read rejects after deletion | I35: O
B36: byte-identical output | J36: O
B37: explicit PDF/text rejection | K37: O
A39: Result | B39: Type(N : Normal, A : Abnormal, B : Boundary) | F39: N | G39: A | H39: A | I39: B | J39: N | K39: A
B40: Passed/Failed
B41: Executed Date
B42: Defect ID
A44: PRECONDITION: Temporary isolated storage root; no production objects. | SOURCE: Arden/apps/api/src/private-notes/content-storage.test.ts | SHA: 953be5418f5489f14cb01c919cb649c207637ec9
A45: Case ID | B45: Exact source test declaration | K45: Input / expected confirmation
A46: U07-01 | B46: writes opaque content references and verifies their content hash | K46: Store and read Unicode text → roundtrip; hash verified
A47: U07-02 | B47: writes opaque content references and verifies their content hash | K47: Read with incorrect SHA-256 → integrity check failure
A48: U07-03 | B48: rejects client-controlled paths and removes objects by opaque URI | K48: Path traversal reference → invalid private URI
A49: U07-04 | B49: rejects client-controlled paths and removes objects by opaque URI | K49: Delete opaque object, read again → read rejects after deletion
A50: U07-05 | B50: stores PDF bytes without UTF-8 conversion and verifies their hash | K50: Store PDF bytes; readPdf → byte-identical output
A51: U07-06 | B51: stores PDF bytes without UTF-8 conversion and verifies their hash | K51: Read PDF as text → explicit PDF/text rejection

Sheet UT-08
A2: Function Code | C2: =Functions!E18 -> UT-008 | F2: Function Name | L2: =Functions!D18 -> apiRequestPolicy
A3: Created By | C3: Khôi | F3: Executed By | L3: Quốc Anh
A4: Lines of code | C4: 98 | F4: Lack of test cases | L4: =IF(OR(Functions!E6="N/A",C4=""),"N/A",MAX(0,ROUNDUP(C4*Functions!E6/1000,0)-O7)) -> N/A
A5: Test requirement | C5: Allow only bounded API routes, methods and idempotency semantics.
A6: Passed | C6: Failed | F6: Untested | L6: N/A/B | O6: Total Test Cases
A7: =COUNTIF(F40:T40,"P") -> 0 | C7: =COUNTIF(F40:T40,"F") -> 0 | F7: =MAX(0,O7-A7-C7) -> 7 | L7: =COUNTIF(F39:T39,"N") -> 4 | M7: =COUNTIF(F39:T39,"A") -> 2 | N7: =COUNTIF(F39:T39,"B") -> 1 | O7: =COUNTA(F9:T9) -> 7
F9: 01 | G9: 02 | H9: 03 | I9: 04 | J9: 05 | K9: 06 | L9: 07
A10: Condition | B10: Precondition
B11: Desktop request policy fixture; bounded payload and route list. | F11: O | G11: O | H11: O | I11: O | J11: O | K11: O | L11: O
B14: Inputs / scenarios
B15: Bounded audience-group edit | F15: O
B16: Shared draft with idempotency key | G16: O
B17: PDF upload on specific route | H17: O
B18: Missing or misplaced idempotency key | I18: O
B19: Existing private note and session routes | J19: O
B20: Known author/review/admin route | K20: O
B21: Method/path/precondition confusion | L21: O
A31: Confirm | B31: Confirm
B32: allowed with precondition | F32: O
B33: allowed | G33: O | J33: O | K33: O
B34: larger body allowed | H34: O
B35: blocked | I35: O | L35: O
A39: Result | B39: Type(N : Normal, A : Abnormal, B : Boundary) | F39: N | G39: N | H39: B | I39: A | J39: N | K39: N | L39: A
B40: Passed/Failed
B41: Executed Date
B42: Defect ID
A44: PRECONDITION: Desktop request policy fixture; bounded payload and route list. | SOURCE: Arden/apps/desktop/src/main/apiRequestPolicy.test.ts | SHA: 953be5418f5489f14cb01c919cb649c207637ec9
A45: Case ID | B45: Exact source test declaration | K45: Input / expected confirmation
A46: U08-01 | B46: bounds audience-group routes and requires group-specific update preconditions | K46: Bounded audience-group edit → allowed with precondition
A47: U08-02 | B47: permits a bounded shared-draft create with its idempotency key | K47: Shared draft with idempotency key → allowed
A48: U08-03 | B48: allows only a bounded PDF upload route to carry a larger request | K48: PDF upload on specific route → larger body allowed
A49: U08-04 | B49: rejects missing, malformed, or misrouted idempotency keys | K49: Missing or misplaced idempotency key → blocked
A50: U08-05 | B50: retains existing private-draft and session requests without broadening routes | K50: Existing private note and session routes → allowed
A51: U08-06 | B51: permits the bounded author, reviewer, publication and admin routes | K51: Known author/review/admin route → allowed
A52: U08-07 | B52: rejects method, precondition and route confusion across knowledge endpoints | K52: Method/path/precondition confusion → blocked

Sheet UT-09
A2: Function Code | C2: =Functions!E19 -> UT-009 | F2: Function Name | L2: =Functions!D19 -> SemanticDocument v1 parser
A3: Created By | C3: Quốc Anh | F3: Executed By | L3: Quốc Anh
A4: Lines of code | C4: 12 | F4: Lack of test cases | L4: =IF(OR(Functions!E6="N/A",C4=""),"N/A",MAX(0,ROUNDUP(C4*Functions!E6/1000,0)-O7)) -> N/A
A5: Test requirement | C5: Preserve canonical IDs, text formatting and safe links.
A6: Passed | C6: Failed | F6: Untested | L6: N/A/B | O6: Total Test Cases
A7: =COUNTIF(F40:T40,"P") -> 0 | C7: =COUNTIF(F40:T40,"F") -> 0 | F7: =MAX(0,O7-A7-C7) -> 7 | L7: =COUNTIF(F39:T39,"N") -> 1 | M7: =COUNTIF(F39:T39,"A") -> 5 | N7: =COUNTIF(F39:T39,"B") -> 1 | O7: =COUNTA(F9:T9) -> 7
F9: 01 | G9: 02 | H9: 03 | I9: 04 | J9: 05 | K9: 06 | L9: 07
A10: Condition | B10: Precondition
B11: Canonical schema v1 document, serializer and parser. | F11: O | G11: O | H11: O | I11: O | J11: O | K11: O | L11: O
B14: Inputs / scenarios
B15: Valid IDs, formatting and links | F15: O
B16: Missing stable block ID | G16: O
B17: Duplicate stable IDs | H17: O
B18: New plain text input | I18: O
B19: Raw plain text parsed as stored doc | J19: O
B20: Unsafe link URL | K20: O
B21: Unknown canonical property | L21: O
A31: Confirm | B31: Confirm
B32: round-trip identical | F32: O
B33: invalid document | G33: O | H33: O | K33: O | L33: O
B34: normalizes into blocks | I34: O
B35: INVALID_PREFIX | J35: O
A39: Result | B39: Type(N : Normal, A : Abnormal, B : Boundary) | F39: N | G39: A | H39: A | I39: B | J39: A | K39: A | L39: A
B40: Passed/Failed
B41: Executed Date
B42: Defect ID
A44: PRECONDITION: Canonical schema v1 document, serializer and parser. | SOURCE: Arden/packages/domain/src/semantic-document.test.ts | SHA: 953be5418f5489f14cb01c919cb649c207637ec9
A45: Case ID | B45: Exact source test declaration | K45: Input / expected confirmation
A46: U09-01 | B46: round-trips stable ids, formatting, and link semantics | K46: Valid IDs, formatting and links → round-trip identical
A47: U09-02 | B47: rejects missing and duplicate stable ids | K47: Missing stable block ID → invalid document
A48: U09-03 | B48: rejects missing and duplicate stable ids | K48: Duplicate stable IDs → invalid document
A49: U09-04 | B49: normalizes new plain-text input without accepting it as stored canonical content | K49: New plain text input → normalizes into blocks
A50: U09-05 | B50: normalizes new plain-text input without accepting it as stored canonical content | K50: Raw plain text parsed as stored doc → INVALID_PREFIX
A51: U09-06 | B51: rejects unsafe links | K51: Unsafe link URL → invalid document
A52: U09-07 | B52: rejects unknown canonical fields instead of silently changing meaning | K52: Unknown canonical property → invalid document

Sheet UT-10
A2: Function Code | C2: =Functions!E20 -> UT-010 | F2: Function Name | L2: =Functions!D20 -> notePreviewReducer
A3: Created By | C3: Khôi | F3: Executed By | L3: Quốc Anh
A4: Lines of code | C4: 37 | F4: Lack of test cases | L4: =IF(OR(Functions!E6="N/A",C4=""),"N/A",MAX(0,ROUNDUP(C4*Functions!E6/1000,0)-O7)) -> N/A
A5: Test requirement | C5: Keep unsaved drafts isolated and avoid unintended server writes.
A6: Passed | C6: Failed | F6: Untested | L6: N/A/B | O6: Total Test Cases
A7: =COUNTIF(F40:T40,"P") -> 0 | C7: =COUNTIF(F40:T40,"F") -> 0 | F7: =MAX(0,O7-A7-C7) -> 8 | L7: =COUNTIF(F39:T39,"N") -> 5 | M7: =COUNTIF(F39:T39,"A") -> 1 | N7: =COUNTIF(F39:T39,"B") -> 2 | O7: =COUNTA(F9:T9) -> 8
F9: 01 | G9: 02 | H9: 03 | I9: 04 | J9: 05 | K9: 06 | L9: 07 | M9: 08
A10: Condition | B10: Precondition
B11: Sample saved notes, reducer actions and local draft state. | F11: O | G11: O | H11: O | I11: O | J11: O | K11: O | L11: O | M11: O
B14: Inputs / scenarios
B15: Edit then switch back | F15: O
B16: Save selected note while second dirty | G16: O
B17: Revert edit to saved value | H17: O
B18: Create new note while prior draft dirty | I18: O
B19: Reset active session | J19: O
B20: Select unknown note ID | K20: O
B21: Discard only selected draft | L21: O
B22: Remove never-saved note | M22: O
A31: Confirm | B31: Confirm
B32: Success / allow | F32: O | H32: O | J32: O
B33: Denied / invalid
B34: Exception / error
B35: No side effect
B36: State preserved | G36: O | I36: O | L36: O | M36: O
B37: Deterministic output | K37: O
B38: Other verified assertion
A39: Result | B39: Type(N : Normal, A : Abnormal, B : Boundary) | F39: N | G39: N | H39: B | I39: N | J39: N | K39: A | L39: N | M39: B
B40: Passed/Failed
B41: Executed Date
B42: Defect ID
A44: PRECONDITION: Sample saved notes, reducer actions and local draft state. | SOURCE: Arden/packages/ui/tests/noteDraftModel.test.ts | SHA: 953be5418f5489f14cb01c919cb649c207637ec9
A45: Case ID | B45: Exact source test declaration | K45: Input / expected confirmation
A46: U10-01 | B46: keeps an unsaved draft when selecting another note and returning | K46: Edit then switch back → draft remains unsaved
A47: U10-02 | B47: saves only the selected note while preserving other drafts | K47: Save selected note while second dirty → other draft retained
A48: U10-03 | B48: does not mark a reverted edit as dirty | K48: Revert edit to saved value → dirty=false
A49: U10-04 | B49: creating and saving a new note preserves the previous unsaved note | K49: Create new note while prior draft dirty → prior draft preserved
A50: U10-05 | B50: clears all drafts and saved preview changes when the session resets | K50: Reset active session → drafts cleared
A51: U10-06 | B51: ignores missing selections and handles an empty workspace | K51: Select unknown note ID → same state; no exception
A52: U10-07 | B52: discards only the selected note | K52: Discard only selected draft → other drafts intact
A53: U10-08 | B53: removes a never-saved local note without deleting saved notes or other drafts | K53: Remove never-saved note → saved notes intact

Sheet UT-11
A2: Function Code | C2: =Functions!E21 -> UT-011 | F2: Function Name | L2: =Functions!D21 -> invitationState / visibleInvitations
A3: Created By | C3: Khôi | F3: Executed By | L3: Quốc Anh
A4: Lines of code | C4: 13 | F4: Lack of test cases | L4: =IF(OR(Functions!E6="N/A",C4=""),"N/A",MAX(0,ROUNDUP(C4*Functions!E6/1000,0)-O7)) -> N/A
A5: Test requirement | C5: Apply invitation expiry, status and counting/sorting rules.
A6: Passed | C6: Failed | F6: Untested | L6: N/A/B | O6: Total Test Cases
A7: =COUNTIF(F40:T40,"P") -> 0 | C7: =COUNTIF(F40:T40,"F") -> 0 | F7: =MAX(0,O7-A7-C7) -> 5 | L7: =COUNTIF(F39:T39,"N") -> 2 | M7: =COUNTIF(F39:T39,"A") -> 1 | N7: =COUNTIF(F39:T39,"B") -> 2 | O7: =COUNTA(F9:T9) -> 5
F9: 01 | G9: 02 | H9: 03 | I9: 04 | J9: 05
A10: Condition | B10: Precondition
B11: Fixed now 2026-10-23, invitation fixtures. | F11: O | G11: O | H11: O | I11: O | J11: O
B14: Inputs / scenarios
B15: PENDING expires tomorrow | F15: O
B16: PENDING expired yesterday | G16: O
B17: Server ACCEPTED or REVOKED | H17: O
B18: Unknown status | I18: O
B19: Mixed list with duplicate joins | J19: O
A31: Confirm | B31: Confirm
B32: PENDING | F32: O
B33: EXPIRED | G33: O
B34: server state retained | H34: O
B35: maps to REVOKED | I35: O
B36: each counted once; pending first | J36: O
A39: Result | B39: Type(N : Normal, A : Abnormal, B : Boundary) | F39: N | G39: B | H39: N | I39: A | J39: B
B40: Passed/Failed
B41: Executed Date
B42: Defect ID
A44: PRECONDITION: Fixed now 2026-10-23, invitation fixtures. | SOURCE: Arden/packages/ui/tests/invitationStatus.test.ts | SHA: 953be5418f5489f14cb01c919cb649c207637ec9
A45: Case ID | B45: Exact source test declaration | K45: Input / expected confirmation
A46: U11-01 | B46: treats a pending invitation past expiry as expired | K46: PENDING expires tomorrow → PENDING
A47: U11-02 | B47: treats a pending invitation past expiry as expired | K47: PENDING expired yesterday → EXPIRED
A48: U11-03 | B48: keeps server outcomes and maps unknown statuses to revoked | K48: Server ACCEPTED or REVOKED → server state retained
A49: U11-04 | B49: keeps server outcomes and maps unknown statuses to revoked | K49: Unknown status → maps to REVOKED
A50: U11-05 | B50: counts every invitation once and orders actionable ones first | K50: Mixed list with duplicate joins → each counted once; pending first

Sheet UT-12
A2: Function Code | C2: =Functions!E22 -> UT-012 | F2: Function Name | L2: =Functions!D22 -> PermissionAwareAnswerer.answer
A3: Created By | C3: Hưng | F3: Executed By
A4: Lines of code | C4: 41 | F4: Lack of test cases | L4: =IF(OR(Functions!E6="N/A",C4=""),"N/A",MAX(0,ROUNDUP(C4*Functions!E6/1000,0)-O7)) -> N/A
A5: Test requirement | C5: Reject nonallowed generation and ungrounded citations; abstain on no evidence.
A6: Passed | C6: Failed | F6: Untested | L6: N/A/B | O6: Total Test Cases
A7: =COUNTIF(F40:T40,"P") -> 0 | C7: =COUNTIF(F40:T40,"F") -> 0 | F7: =MAX(0,O7-A7-C7) -> 3 | L7: =COUNTIF(F39:T39,"N") -> 1 | M7: =COUNTIF(F39:T39,"A") -> 1 | N7: =COUNTIF(F39:T39,"B") -> 1 | O7: =COUNTA(F9:T9) -> 3
F9: 01 | G9: 02 | H9: 03
A10: Condition | B10: Precondition
B11: Fake retriever/generator, UUID allowlist, MFA evidence. | F11: O | G11: O | H11: O
B14: Inputs / scenarios
B15: Retrieved allowed chunk + cited generator | F15: O
B16: Retrieved chunk from other generation | G16: O
B17: Retriever returns zero chunks | H17: O
A31: Confirm | B31: Confirm
B32: ANSWERED; citation grounded | F32: O
B33: throws outside allow-list | G33: O
B34: INSUFFICIENT_EVIDENCE; no citation | H34: O
A39: Result | B39: Type(N : Normal, A : Abnormal, B : Boundary) | F39: N | G39: A | H39: B
B40: Passed/Failed
B41: Executed Date
B42: Defect ID
A44: PRECONDITION: Fake retriever/generator, UUID allowlist, MFA evidence. | SOURCE: Arden-AI/tests/test_answering.py | SHA: cc0b4d2cf042be4d54c92abecd90f8ac7c1da3ec
A45: Case ID | B45: Exact source test declaration | K45: Input / expected confirmation
A46: U12-01 | B46: test_answerer_returns_only_retrieved_citations | K46: Retrieved allowed chunk + cited generator → ANSWERED; citation grounded
A47: U12-02 | B47: test_answerer_rejects_evidence_outside_core_allow_list | K47: Retrieved chunk from other generation → throws outside allow-list
A48: U12-03 | B48: test_answerer_abstains_when_retrieval_is_empty | K48: Retriever returns zero chunks → INSUFFICIENT_EVIDENCE; no citation

Sheet UT-13
A2: Function Code | C2: =Functions!E23 -> UT-013 | F2: Function Name | L2: =Functions!D23 -> chunk_markdown
A3: Created By | C3: Hưng | F3: Executed By
A4: Lines of code | C4: 86 | F4: Lack of test cases | L4: =IF(OR(Functions!E6="N/A",C4=""),"N/A",MAX(0,ROUNDUP(C4*Functions!E6/1000,0)-O7)) -> N/A
A5: Test requirement | C5: Preserve chunk offsets, parent section and token limits.
A6: Passed | C6: Failed | F6: Untested | L6: N/A/B | O6: Total Test Cases
A7: =COUNTIF(F40:T40,"P") -> 0 | C7: =COUNTIF(F40:T40,"F") -> 0 | F7: =MAX(0,O7-A7-C7) -> 2 | L7: =COUNTIF(F39:T39,"N") -> 1 | M7: =COUNTIF(F39:T39,"A") -> 0 | N7: =COUNTIF(F39:T39,"B") -> 1 | O7: =COUNTA(F9:T9) -> 2
F9: 01 | G9: 02
A10: Condition | B10: Precondition
B11: Compiled semantic document with long security section. | F11: O | G11: O
B14: Inputs / scenarios
B15: Chunk text with overlap below size | F15: O
B16: Overlap >= chunk size | G16: O
A31: Confirm | B31: Confirm
B32: offsets and parent IDs preserved | F32: O
B33: error: overlap must be smaller | G33: O
A39: Result | B39: Type(N : Normal, A : Abnormal, B : Boundary) | F39: N | G39: B
B40: Passed/Failed
B41: Executed Date
B42: Defect ID
A44: PRECONDITION: Compiled semantic document with long security section. | SOURCE: Arden-AI/tests/test_chunking.py | SHA: cc0b4d2cf042be4d54c92abecd90f8ac7c1da3ec
A45: Case ID | B45: Exact source test declaration | K45: Input / expected confirmation
A46: U13-01 | B46: test_langchain_chunking_preserves_offsets_and_parent_sections | K46: Chunk text with overlap below size → offsets and parent IDs preserved
A47: U13-02 | B47: test_chunking_rejects_invalid_overlap | K47: Overlap >= chunk size → error: overlap must be smaller

Sheet UT-14
A2: Function Code | C2: =Functions!E24 -> UT-014 | F2: Function Name | L2: =Functions!D24 -> IndexGenerationRequest
A3: Created By | C3: Hưng | F3: Executed By
A4: Lines of code | C4: 49 | F4: Lack of test cases | L4: =IF(OR(Functions!E6="N/A",C4=""),"N/A",MAX(0,ROUNDUP(C4*Functions!E6/1000,0)-O7)) -> N/A
A5: Test requirement | C5: Validate strict generation payload, hash, PDF bytes and JSON schema.
A6: Passed | C6: Failed | F6: Untested | L6: N/A/B | O6: Total Test Cases
A7: =COUNTIF(F40:T40,"P") -> 0 | C7: =COUNTIF(F40:T40,"F") -> 0 | F7: =MAX(0,O7-A7-C7) -> 6 | L7: =COUNTIF(F39:T39,"N") -> 3 | M7: =COUNTIF(F39:T39,"A") -> 2 | N7: =COUNTIF(F39:T39,"B") -> 1 | O7: =COUNTA(F9:T9) -> 6
F9: 01 | G9: 02 | H9: 03 | I9: 04 | J9: 05 | K9: 06
A10: Condition | B10: Precondition
B11: Versioned camelCase indexing request with stable UUIDs. | F11: O | G11: O | H11: O | I11: O | J11: O | K11: O
B14: Inputs / scenarios
B15: Valid exact camelCase payload | F15: O
B16: Unexpected callbackUrl property | G16: O
B17: Future contractVersion | H17: O
B18: Snapshot text/hash disagree | I18: O
B19: Raw PDF bytes match hash | J19: O
B20: Export generated schema | K20: O
A31: Confirm | B31: Confirm
B32: parsed UUID and content | F32: O
B33: validation error | G33: O | H33: O | I33: O
B34: pdf_bytes matches input | J34: O
B35: concrete contract objects | K35: O
A39: Result | B39: Type(N : Normal, A : Abnormal, B : Boundary) | F39: N | G39: A | H39: B | I39: A | J39: N | K39: N
B40: Passed/Failed
B41: Executed Date
B42: Defect ID
A44: PRECONDITION: Versioned camelCase indexing request with stable UUIDs. | SOURCE: Arden-AI/tests/test_contracts.py | SHA: cc0b4d2cf042be4d54c92abecd90f8ac7c1da3ec
A45: Case ID | B45: Exact source test declaration | K45: Input / expected confirmation
A46: U14-01 | B46: test_index_request_uses_strict_camel_case_contract | K46: Valid exact camelCase payload → parsed UUID and content
A47: U14-02 | B47: test_index_request_rejects_unknown_fields | K47: Unexpected callbackUrl property → validation error
A48: U14-03 | B48: test_index_request_rejects_future_contract_versions | K48: Future contractVersion → validation error
A49: U14-04 | B49: test_index_request_rejects_snapshot_hash_mismatch | K49: Snapshot text/hash disagree → validation error
A50: U14-05 | B50: test_index_request_accepts_integrity_checked_pdf_bytes | K50: Raw PDF bytes match hash → pdf_bytes matches input
A51: U14-06 | B51: test_exported_indexing_schema_contains_concrete_contracts | K51: Export generated schema → concrete contract objects

Sheet UT-15
A2: Function Code | C2: =Functions!E25 -> UT-015 | F2: Function Name | L2: =Functions!D25 -> citationPageForSource
A3: Created By | C3: Hưng | F3: Executed By | L3: Quốc Anh
A4: Lines of code | C4: 10 | F4: Lack of test cases | L4: =IF(OR(Functions!E6="N/A",C4=""),"N/A",MAX(0,ROUNDUP(C4*Functions!E6/1000,0)-O7)) -> N/A
A5: Test requirement | C5: Resolve PDF page from cited block or fallback parent; ignore non-PDF.
A6: Passed | C6: Failed | F6: Untested | L6: N/A/B | O6: Total Test Cases
A7: =COUNTIF(F40:T40,"P") -> 0 | C7: =COUNTIF(F40:T40,"F") -> 0 | F7: =MAX(0,O7-A7-C7) -> 3 | L7: =COUNTIF(F39:T39,"N") -> 1 | M7: =COUNTIF(F39:T39,"A") -> 1 | N7: =COUNTIF(F39:T39,"B") -> 1 | O7: =COUNTA(F9:T9) -> 3
F9: 01 | G9: 02 | H9: 03
A10: Condition | B10: Precondition
B11: Cited semantic source blocks and optional parent reference. | F11: O | G11: O | H11: O
B14: Inputs / scenarios
B15: PDF block with page number | F15: O
B16: Page stored only on parent block | G16: O
B17: Non-PDF block | H17: O
A31: Confirm | B31: Confirm
B32: source PDF page returned | F32: O
B33: parent page returned | G33: O
B34: no PDF navigation page | H34: O
A39: Result | B39: Type(N : Normal, A : Abnormal, B : Boundary) | F39: N | G39: B | H39: A
B40: Passed/Failed
B41: Executed Date
B42: Defect ID
A44: PRECONDITION: Cited semantic source blocks and optional parent reference. | SOURCE: Arden/apps/api/src/answers/citation-page.test.ts | SHA: 953be5418f5489f14cb01c919cb649c207637ec9
A45: Case ID | B45: Exact source test declaration | K45: Input / expected confirmation
A46: U15-01 | B46: reads the PDF page from a source block | K46: PDF block with page number → source PDF page returned
A47: U15-02 | B47: falls back to the parent section and ignores non-PDF blocks | K47: Page stored only on parent block → parent page returned
A48: U15-03 | B48: falls back to the parent section and ignores non-PDF blocks | K48: Non-PDF block → no PDF navigation page

Sheet UT-16
A2: Function Code | C2: =Functions!E26 -> UT-016 | F2: Function Name | L2: =Functions!D26 -> knowledgeAudience selection
A3: Created By | C3: Hưng | F3: Executed By | L3: Quốc Anh
A4: Lines of code | C4: 14 | F4: Lack of test cases | L4: =IF(OR(Functions!E6="N/A",C4=""),"N/A",MAX(0,ROUNDUP(C4*Functions!E6/1000,0)-O7)) -> N/A
A5: Test requirement | C5: Filter managed audience by scope and disallow invalid choices.
A6: Passed | C6: Failed | F6: Untested | L6: N/A/B | O6: Total Test Cases
A7: =COUNTIF(F40:T40,"P") -> 0 | C7: =COUNTIF(F40:T40,"F") -> 0 | F7: =MAX(0,O7-A7-C7) -> 3 | L7: =COUNTIF(F39:T39,"N") -> 1 | M7: =COUNTIF(F39:T39,"A") -> 1 | N7: =COUNTIF(F39:T39,"B") -> 1 | O7: =COUNTA(F9:T9) -> 3
F9: 01 | G9: 02 | H9: 03
A10: Condition | B10: Precondition
B11: Org and department audience fixtures plus selected scope. | F11: O | G11: O | H11: O
B14: Inputs / scenarios
B15: Organization and department scopes | F15: O
B16: Switch ORGANIZATION to DEPARTMENT | G16: O
B17: Empty/unknown/duplicate selected audiences | H17: O
A31: Confirm | B31: Confirm
B32: only matching managed options | F32: O
B33: ALL_MEMBERS removed | G33: O
B34: selection rejected | H34: O
A39: Result | B39: Type(N : Normal, A : Abnormal, B : Boundary) | F39: N | G39: B | H39: A
B40: Passed/Failed
B41: Executed Date
B42: Defect ID
A44: PRECONDITION: Org and department audience fixtures plus selected scope. | SOURCE: Arden/packages/ui/tests/knowledgeAudience.test.ts | SHA: 953be5418f5489f14cb01c919cb649c207637ec9
A45: Case ID | B45: Exact source test declaration | K45: Input / expected confirmation
A46: U16-01 | B46: offers managed audiences only at their matching scope and groups at either scope | K46: Organization and department scopes → only matching managed options
A47: U16-02 | B47: removes ALL_MEMBERS when switching from Organization to Department | K47: Switch ORGANIZATION to DEPARTMENT → ALL_MEMBERS removed
A48: U16-03 | B48: rejects empty, duplicate, unknown and out-of-scope selections | K48: Empty/unknown/duplicate selected audiences → selection rejected

Sheet UT-17
A2: Function Code | C2: =Functions!E27 -> UT-017 | F2: Function Name | L2: =Functions!D27 -> LocalFlow1TestAuthProvider
A3: Created By | C3: Kiệt | F3: Executed By | L3: Quốc Anh
A4: Lines of code | C4: 56 | F4: Lack of test cases | L4: =IF(OR(Functions!E6="N/A",C4=""),"N/A",MAX(0,ROUNDUP(C4*Functions!E6/1000,0)-O7)) -> N/A
A5: Test requirement | C5: Constrain synthetic account, DB target and revocable test sessions.
A6: Passed | C6: Failed | F6: Untested | L6: N/A/B | O6: Total Test Cases
A7: =COUNTIF(F40:T40,"P") -> 0 | C7: =COUNTIF(F40:T40,"F") -> 0 | F7: =MAX(0,O7-A7-C7) -> 6 | L7: =COUNTIF(F39:T39,"N") -> 2 | M7: =COUNTIF(F39:T39,"A") -> 3 | N7: =COUNTIF(F39:T39,"B") -> 1 | O7: =COUNTA(F9:T9) -> 6
F9: 01 | G9: 02 | H9: 03 | I9: 04 | J9: 05 | K9: 06
A10: Condition | B10: Precondition
B11: Isolated loopback test DB; example.test fixtures only. | F11: O | G11: O | H11: O | I11: O | J11: O | K11: O
B14: Inputs / scenarios
B15: Known loopback/local DB | F15: O
B16: External DB binding | G16: O
